[2025-03-27T15:09:14.948+0000] {local_task_job_runner.py:123} INFO - ::group::Pre task execution logs
[2025-03-27T15:09:14.971+0000] {taskinstance.py:2612} INFO - Dependencies all met for dep_context=non-requeueable deps ti=<TaskInstance: minio_upload_test.upload_file_to_minio manual__2025-03-27T15:09:10.031728+00:00 [queued]>
[2025-03-27T15:09:14.985+0000] {taskinstance.py:2612} INFO - Dependencies all met for dep_context=requeueable deps ti=<TaskInstance: minio_upload_test.upload_file_to_minio manual__2025-03-27T15:09:10.031728+00:00 [queued]>
[2025-03-27T15:09:14.986+0000] {taskinstance.py:2865} INFO - Starting attempt 1 of 1
[2025-03-27T15:09:15.011+0000] {taskinstance.py:2888} INFO - Executing <Task(_PythonDecoratedOperator): upload_file_to_minio> on 2025-03-27 15:09:10.031728+00:00
[2025-03-27T15:09:15.034+0000] {standard_task_runner.py:104} INFO - Running: ['***', 'tasks', 'run', 'minio_upload_test', 'upload_file_to_minio', 'manual__2025-03-27T15:09:10.031728+00:00', '--job-id', '89', '--raw', '--subdir', 'DAGS_FOLDER/minio_test_dag.py', '--cfg-path', '/tmp/tmp7_8h6ucd']
[2025-03-27T15:09:15.035+0000] {warnings.py:112} WARNING - /home/***/.local/lib/python3.12/site-packages/***/task/task_runner/standard_task_runner.py:70: DeprecationWarning: This process (pid=215) is multi-threaded, use of fork() may lead to deadlocks in the child.
  pid = os.fork()

[2025-03-27T15:09:15.042+0000] {standard_task_runner.py:105} INFO - Job 89: Subtask upload_file_to_minio
[2025-03-27T15:09:15.042+0000] {standard_task_runner.py:72} INFO - Started process 217 to run task
[2025-03-27T15:09:15.136+0000] {task_command.py:467} INFO - Running <TaskInstance: minio_upload_test.upload_file_to_minio manual__2025-03-27T15:09:10.031728+00:00 [running]> on host 75fbd25ffde3
[2025-03-27T15:09:15.313+0000] {taskinstance.py:3131} INFO - Exporting env vars: AIRFLOW_CTX_DAG_OWNER='***' AIRFLOW_CTX_DAG_ID='minio_upload_test' AIRFLOW_CTX_TASK_ID='upload_file_to_minio' AIRFLOW_CTX_EXECUTION_DATE='2025-03-27T15:09:10.031728+00:00' AIRFLOW_CTX_TRY_NUMBER='1' AIRFLOW_CTX_DAG_RUN_ID='manual__2025-03-27T15:09:10.031728+00:00'
[2025-03-27T15:09:15.318+0000] {taskinstance.py:731} INFO - ::endgroup::
[2025-03-27T15:09:15.366+0000] {taskinstance.py:3310} ERROR - Task failed with exception
Traceback (most recent call last):
  File "/home/airflow/.local/lib/python3.12/site-packages/airflow/models/taskinstance.py", line 767, in _execute_task
    result = _execute_callable(context=context, **execute_callable_kwargs)
             ^^^^^^^^^^^^^^^^^^^^^^^^^^^^^^^^^^^^^^^^^^^^^^^^^^^^^^^^^^^^^
  File "/home/airflow/.local/lib/python3.12/site-packages/airflow/models/taskinstance.py", line 733, in _execute_callable
    return ExecutionCallableRunner(
           ^^^^^^^^^^^^^^^^^^^^^^^^
  File "/home/airflow/.local/lib/python3.12/site-packages/airflow/utils/operator_helpers.py", line 252, in run
    return self.func(*args, **kwargs)
           ^^^^^^^^^^^^^^^^^^^^^^^^^^
  File "/home/airflow/.local/lib/python3.12/site-packages/airflow/models/baseoperator.py", line 406, in wrapper
    return func(self, *args, **kwargs)
           ^^^^^^^^^^^^^^^^^^^^^^^^^^^
  File "/home/airflow/.local/lib/python3.12/site-packages/airflow/decorators/base.py", line 266, in execute
    return_value = super().execute(context)
                   ^^^^^^^^^^^^^^^^^^^^^^^^
  File "/home/airflow/.local/lib/python3.12/site-packages/airflow/models/baseoperator.py", line 406, in wrapper
    return func(self, *args, **kwargs)
           ^^^^^^^^^^^^^^^^^^^^^^^^^^^
  File "/home/airflow/.local/lib/python3.12/site-packages/airflow/operators/python.py", line 238, in execute
    return_value = self.execute_callable()
                   ^^^^^^^^^^^^^^^^^^^^^^^
  File "/home/airflow/.local/lib/python3.12/site-packages/airflow/operators/python.py", line 256, in execute_callable
    return runner.run(*self.op_args, **self.op_kwargs)
           ^^^^^^^^^^^^^^^^^^^^^^^^^^^^^^^^^^^^^^^^^^^
  File "/home/airflow/.local/lib/python3.12/site-packages/airflow/utils/operator_helpers.py", line 252, in run
    return self.func(*args, **kwargs)
           ^^^^^^^^^^^^^^^^^^^^^^^^^^
  File "/opt/airflow/dags/minio_test_dag.py", line 84, in upload_file_to_minio
    connector = MinioConnector(
                ^^^^^^^^^^^^^^^
  File "/opt/airflow/connectors/minio.py", line 20, in __init__
    self.client = Minio(
                  ^^^^^^
  File "/home/airflow/.local/lib/python3.12/site-packages/minio/api.py", line 152, in __init__
    self._base_url = BaseURL(
                     ^^^^^^^^
  File "/home/airflow/.local/lib/python3.12/site-packages/minio/helpers.py", line 551, in __init__
    url = _parse_url(endpoint)
          ^^^^^^^^^^^^^^^^^^^^
  File "/home/airflow/.local/lib/python3.12/site-packages/minio/helpers.py", line 512, in _parse_url
    raise ValueError("path in endpoint is not allowed")
ValueError: path in endpoint is not allowed
[2025-03-27T15:09:15.401+0000] {taskinstance.py:1225} INFO - Marking task as FAILED. dag_id=minio_upload_test, task_id=upload_file_to_minio, run_id=manual__2025-03-27T15:09:10.031728+00:00, execution_date=20250327T150910, start_date=20250327T150914, end_date=20250327T150915
[2025-03-27T15:09:15.435+0000] {taskinstance.py:340} INFO - ::group::Post task execution logs
[2025-03-27T15:09:15.437+0000] {standard_task_runner.py:124} ERROR - Failed to execute job 89 for task upload_file_to_minio (path in endpoint is not allowed; 217)
Traceback (most recent call last):
  File "/home/airflow/.local/lib/python3.12/site-packages/airflow/task/task_runner/standard_task_runner.py", line 117, in _start_by_fork
    ret = args.func(args, dag=self.dag)
          ^^^^^^^^^^^^^^^^^^^^^^^^^^^^^
  File "/home/airflow/.local/lib/python3.12/site-packages/airflow/cli/cli_config.py", line 49, in command
    return func(*args, **kwargs)
           ^^^^^^^^^^^^^^^^^^^^^
  File "/home/airflow/.local/lib/python3.12/site-packages/airflow/utils/cli.py", line 115, in wrapper
    return f(*args, **kwargs)
           ^^^^^^^^^^^^^^^^^^
  File "/home/airflow/.local/lib/python3.12/site-packages/airflow/cli/commands/task_command.py", line 483, in task_run
    task_return_code = _run_task_by_selected_method(args, _dag, ti)
                       ^^^^^^^^^^^^^^^^^^^^^^^^^^^^^^^^^^^^^^^^^^^^
  File "/home/airflow/.local/lib/python3.12/site-packages/airflow/cli/commands/task_command.py", line 256, in _run_task_by_selected_method
    return _run_raw_task(args, ti)
           ^^^^^^^^^^^^^^^^^^^^^^^
  File "/home/airflow/.local/lib/python3.12/site-packages/airflow/cli/commands/task_command.py", line 341, in _run_raw_task
    return ti._run_raw_task(
           ^^^^^^^^^^^^^^^^^
  File "/home/airflow/.local/lib/python3.12/site-packages/airflow/utils/session.py", line 97, in wrapper
    return func(*args, session=session, **kwargs)
           ^^^^^^^^^^^^^^^^^^^^^^^^^^^^^^^^^^^^^^
  File "/home/airflow/.local/lib/python3.12/site-packages/airflow/models/taskinstance.py", line 3004, in _run_raw_task
    return _run_raw_task(
           ^^^^^^^^^^^^^^
  File "/home/airflow/.local/lib/python3.12/site-packages/airflow/models/taskinstance.py", line 273, in _run_raw_task
    TaskInstance._execute_task_with_callbacks(
  File "/home/airflow/.local/lib/python3.12/site-packages/airflow/models/taskinstance.py", line 3158, in _execute_task_with_callbacks
    result = self._execute_task(context, task_orig)
             ^^^^^^^^^^^^^^^^^^^^^^^^^^^^^^^^^^^^^^
  File "/home/airflow/.local/lib/python3.12/site-packages/airflow/models/taskinstance.py", line 3182, in _execute_task
    return _execute_task(self, context, task_orig)
           ^^^^^^^^^^^^^^^^^^^^^^^^^^^^^^^^^^^^^^^
  File "/home/airflow/.local/lib/python3.12/site-packages/airflow/models/taskinstance.py", line 767, in _execute_task
    result = _execute_callable(context=context, **execute_callable_kwargs)
             ^^^^^^^^^^^^^^^^^^^^^^^^^^^^^^^^^^^^^^^^^^^^^^^^^^^^^^^^^^^^^
  File "/home/airflow/.local/lib/python3.12/site-packages/airflow/models/taskinstance.py", line 733, in _execute_callable
    return ExecutionCallableRunner(
           ^^^^^^^^^^^^^^^^^^^^^^^^
  File "/home/airflow/.local/lib/python3.12/site-packages/airflow/utils/operator_helpers.py", line 252, in run
    return self.func(*args, **kwargs)
           ^^^^^^^^^^^^^^^^^^^^^^^^^^
  File "/home/airflow/.local/lib/python3.12/site-packages/airflow/models/baseoperator.py", line 406, in wrapper
    return func(self, *args, **kwargs)
           ^^^^^^^^^^^^^^^^^^^^^^^^^^^
  File "/home/airflow/.local/lib/python3.12/site-packages/airflow/decorators/base.py", line 266, in execute
    return_value = super().execute(context)
                   ^^^^^^^^^^^^^^^^^^^^^^^^
  File "/home/airflow/.local/lib/python3.12/site-packages/airflow/models/baseoperator.py", line 406, in wrapper
    return func(self, *args, **kwargs)
           ^^^^^^^^^^^^^^^^^^^^^^^^^^^
  File "/home/airflow/.local/lib/python3.12/site-packages/airflow/operators/python.py", line 238, in execute
    return_value = self.execute_callable()
                   ^^^^^^^^^^^^^^^^^^^^^^^
  File "/home/airflow/.local/lib/python3.12/site-packages/airflow/operators/python.py", line 256, in execute_callable
    return runner.run(*self.op_args, **self.op_kwargs)
           ^^^^^^^^^^^^^^^^^^^^^^^^^^^^^^^^^^^^^^^^^^^
  File "/home/airflow/.local/lib/python3.12/site-packages/airflow/utils/operator_helpers.py", line 252, in run
    return self.func(*args, **kwargs)
           ^^^^^^^^^^^^^^^^^^^^^^^^^^
  File "/opt/airflow/dags/minio_test_dag.py", line 84, in upload_file_to_minio
    connector = MinioConnector(
                ^^^^^^^^^^^^^^^
  File "/opt/airflow/connectors/minio.py", line 20, in __init__
    self.client = Minio(
                  ^^^^^^
  File "/home/airflow/.local/lib/python3.12/site-packages/minio/api.py", line 152, in __init__
    self._base_url = BaseURL(
                     ^^^^^^^^
  File "/home/airflow/.local/lib/python3.12/site-packages/minio/helpers.py", line 551, in __init__
    url = _parse_url(endpoint)
          ^^^^^^^^^^^^^^^^^^^^
  File "/home/airflow/.local/lib/python3.12/site-packages/minio/helpers.py", line 512, in _parse_url
    raise ValueError("path in endpoint is not allowed")
ValueError: path in endpoint is not allowed
[2025-03-27T15:09:15.528+0000] {local_task_job_runner.py:266} INFO - Task exited with return code 1
[2025-03-27T15:09:15.587+0000] {taskinstance.py:3900} INFO - 0 downstream tasks scheduled from follow-on schedule check
[2025-03-27T15:09:15.598+0000] {local_task_job_runner.py:245} INFO - ::endgroup::
