[2025-03-25T22:30:09.911+0000] {local_task_job_runner.py:123} INFO - ::group::Pre task execution logs
[2025-03-25T22:30:09.999+0000] {taskinstance.py:2612} INFO - Dependencies all met for dep_context=non-requeueable deps ti=<TaskInstance: get_inaturalist_data_roadkill.get_all_data scheduled__2025-03-25T22:00:00+00:00 [queued]>
[2025-03-25T22:30:10.046+0000] {taskinstance.py:2612} INFO - Dependencies all met for dep_context=requeueable deps ti=<TaskInstance: get_inaturalist_data_roadkill.get_all_data scheduled__2025-03-25T22:00:00+00:00 [queued]>
[2025-03-25T22:30:10.049+0000] {taskinstance.py:2865} INFO - Starting attempt 1 of 4
[2025-03-25T22:30:10.113+0000] {taskinstance.py:2888} INFO - Executing <Task(_PythonDecoratedOperator): get_all_data> on 2025-03-25 22:00:00+00:00
[2025-03-25T22:30:10.198+0000] {warnings.py:112} WARNING - /home/***/.local/lib/python3.12/site-packages/***/task/task_runner/standard_task_runner.py:70: DeprecationWarning: This process (pid=1784) is multi-threaded, use of fork() may lead to deadlocks in the child.
  pid = os.fork()

[2025-03-25T22:30:10.202+0000] {standard_task_runner.py:72} INFO - Started process 1790 to run task
[2025-03-25T22:30:10.199+0000] {standard_task_runner.py:104} INFO - Running: ['***', 'tasks', 'run', 'get_inaturalist_data_roadkill', 'get_all_data', 'scheduled__2025-03-25T22:00:00+00:00', '--job-id', '118', '--raw', '--subdir', 'DAGS_FOLDER/inaturalist_dag.py', '--cfg-path', '/tmp/tmpupzybm5q']
[2025-03-25T22:30:10.211+0000] {standard_task_runner.py:105} INFO - Job 118: Subtask get_all_data
[2025-03-25T22:30:10.379+0000] {task_command.py:467} INFO - Running <TaskInstance: get_inaturalist_data_roadkill.get_all_data scheduled__2025-03-25T22:00:00+00:00 [running]> on host 5ed333479984
[2025-03-25T22:30:10.629+0000] {taskinstance.py:3131} INFO - Exporting env vars: AIRFLOW_CTX_DAG_OWNER='***' AIRFLOW_CTX_DAG_ID='get_inaturalist_data_roadkill' AIRFLOW_CTX_TASK_ID='get_all_data' AIRFLOW_CTX_EXECUTION_DATE='2025-03-25T22:00:00+00:00' AIRFLOW_CTX_TRY_NUMBER='1' AIRFLOW_CTX_DAG_RUN_ID='scheduled__2025-03-25T22:00:00+00:00'
[2025-03-25T22:30:10.639+0000] {taskinstance.py:731} INFO - ::endgroup::
[2025-03-25T22:30:10.661+0000] {inaturalist_dag.py:150} INFO - Getting data from keyword: roadkill
[2025-03-25T22:30:10.712+0000] {inaturalist_dag.py:41} INFO - Maximum id 121380850 for the request
[2025-03-25T22:30:23.349+0000] {inaturalist_dag.py:58} INFO - Got 200 results
[2025-03-25T22:30:23.949+0000] {inaturalist_dag.py:163} INFO - Extracted 200 observations
[2025-03-25T22:30:23.969+0000] {inaturalist_dag.py:41} INFO - Maximum id 124391146 for the request
[2025-03-25T22:30:36.401+0000] {job.py:229} INFO - Heartbeat recovered after 11.78 seconds
[2025-03-25T22:31:18.369+0000] {inaturalist_dag.py:58} INFO - Got 200 results
[2025-03-25T22:31:18.877+0000] {inaturalist_dag.py:163} INFO - Extracted 400 observations
[2025-03-25T22:31:18.998+0000] {inaturalist_dag.py:41} INFO - Maximum id 127401020 for the request
[2025-03-25T22:31:22.467+0000] {job.py:229} INFO - Heartbeat recovered after 49.92 seconds
[2025-03-25T22:31:27.571+0000] {inaturalist_dag.py:58} INFO - Got 200 results
[2025-03-25T22:31:27.684+0000] {inaturalist_dag.py:163} INFO - Extracted 600 observations
[2025-03-25T22:31:27.686+0000] {inaturalist_dag.py:41} INFO - Maximum id 130779139 for the request
[2025-03-25T22:31:34.066+0000] {inaturalist_dag.py:58} INFO - Got 200 results
[2025-03-25T22:31:34.166+0000] {inaturalist_dag.py:163} INFO - Extracted 800 observations
[2025-03-25T22:31:34.167+0000] {inaturalist_dag.py:41} INFO - Maximum id 132841073 for the request
[2025-03-25T22:31:43.859+0000] {inaturalist_dag.py:58} INFO - Got 200 results
[2025-03-25T22:31:43.948+0000] {inaturalist_dag.py:163} INFO - Extracted 1000 observations
[2025-03-25T22:31:43.950+0000] {inaturalist_dag.py:41} INFO - Maximum id 135640708 for the request
[2025-03-25T22:31:52.814+0000] {inaturalist_dag.py:58} INFO - Got 200 results
[2025-03-25T22:31:52.925+0000] {inaturalist_dag.py:163} INFO - Extracted 1200 observations
[2025-03-25T22:31:52.927+0000] {inaturalist_dag.py:41} INFO - Maximum id 136778919 for the request
[2025-03-25T22:32:07.148+0000] {inaturalist_dag.py:58} INFO - Got 200 results
[2025-03-25T22:32:07.369+0000] {job.py:229} INFO - Heartbeat recovered after 11.59 seconds
[2025-03-25T22:32:07.544+0000] {inaturalist_dag.py:163} INFO - Extracted 1400 observations
[2025-03-25T22:32:07.579+0000] {inaturalist_dag.py:41} INFO - Maximum id 139280447 for the request
[2025-03-25T22:32:14.548+0000] {inaturalist_dag.py:58} INFO - Got 200 results
[2025-03-25T22:32:14.646+0000] {inaturalist_dag.py:163} INFO - Extracted 1600 observations
[2025-03-25T22:32:14.657+0000] {inaturalist_dag.py:41} INFO - Maximum id 140950225 for the request
[2025-03-25T22:32:20.349+0000] {inaturalist_dag.py:58} INFO - Got 200 results
[2025-03-25T22:32:20.439+0000] {inaturalist_dag.py:163} INFO - Extracted 1800 observations
[2025-03-25T22:32:20.441+0000] {inaturalist_dag.py:41} INFO - Maximum id 141656959 for the request
[2025-03-25T22:32:25.848+0000] {inaturalist_dag.py:58} INFO - Got 200 results
[2025-03-25T22:32:26.119+0000] {inaturalist_dag.py:163} INFO - Extracted 2000 observations
[2025-03-25T22:32:26.170+0000] {inaturalist_dag.py:41} INFO - Maximum id 141743507 for the request
[2025-03-25T22:32:33.910+0000] {inaturalist_dag.py:58} INFO - Got 200 results
[2025-03-25T22:32:35.007+0000] {inaturalist_dag.py:163} INFO - Extracted 2200 observations
[2025-03-25T22:32:35.687+0000] {inaturalist_dag.py:41} INFO - Maximum id 141745559 for the request
[2025-03-25T22:32:50.619+0000] {taskinstance.py:3310} ERROR - Task failed with exception
Traceback (most recent call last):
  File "/home/airflow/.local/lib/python3.12/site-packages/urllib3/connection.py", line 196, in _new_conn
    sock = connection.create_connection(
           ^^^^^^^^^^^^^^^^^^^^^^^^^^^^^
  File "/home/airflow/.local/lib/python3.12/site-packages/urllib3/util/connection.py", line 60, in create_connection
    for res in socket.getaddrinfo(host, port, family, socket.SOCK_STREAM):
               ^^^^^^^^^^^^^^^^^^^^^^^^^^^^^^^^^^^^^^^^^^^^^^^^^^^^^^^^^^
  File "/usr/local/lib/python3.12/socket.py", line 976, in getaddrinfo
    for res in _socket.getaddrinfo(host, port, family, type, proto, flags):
               ^^^^^^^^^^^^^^^^^^^^^^^^^^^^^^^^^^^^^^^^^^^^^^^^^^^^^^^^^^^
socket.gaierror: [Errno -3] Temporary failure in name resolution

The above exception was the direct cause of the following exception:

Traceback (most recent call last):
  File "/home/airflow/.local/lib/python3.12/site-packages/urllib3/connectionpool.py", line 789, in urlopen
    response = self._make_request(
               ^^^^^^^^^^^^^^^^^^^
  File "/home/airflow/.local/lib/python3.12/site-packages/urllib3/connectionpool.py", line 490, in _make_request
    raise new_e
  File "/home/airflow/.local/lib/python3.12/site-packages/urllib3/connectionpool.py", line 466, in _make_request
    self._validate_conn(conn)
  File "/home/airflow/.local/lib/python3.12/site-packages/urllib3/connectionpool.py", line 1095, in _validate_conn
    conn.connect()
  File "/home/airflow/.local/lib/python3.12/site-packages/urllib3/connection.py", line 615, in connect
    self.sock = sock = self._new_conn()
                       ^^^^^^^^^^^^^^^^
  File "/home/airflow/.local/lib/python3.12/site-packages/urllib3/connection.py", line 203, in _new_conn
    raise NameResolutionError(self.host, self, e) from e
urllib3.exceptions.NameResolutionError: <urllib3.connection.HTTPSConnection object at 0xffff8b5204d0>: Failed to resolve 'api.inaturalist.org' ([Errno -3] Temporary failure in name resolution)

The above exception was the direct cause of the following exception:

Traceback (most recent call last):
  File "/home/airflow/.local/lib/python3.12/site-packages/requests/adapters.py", line 667, in send
    resp = conn.urlopen(
           ^^^^^^^^^^^^^
  File "/home/airflow/.local/lib/python3.12/site-packages/urllib3/connectionpool.py", line 843, in urlopen
    retries = retries.increment(
              ^^^^^^^^^^^^^^^^^^
  File "/home/airflow/.local/lib/python3.12/site-packages/urllib3/util/retry.py", line 519, in increment
    raise MaxRetryError(_pool, url, reason) from reason  # type: ignore[arg-type]
    ^^^^^^^^^^^^^^^^^^^^^^^^^^^^^^^^^^^^^^^^^^^^^^^^^^^
urllib3.exceptions.MaxRetryError: HTTPSConnectionPool(host='api.inaturalist.org', port=443): Max retries exceeded with url: /v1/observations?geo=true&iconic_taxa=Amphibia%2CAves%2CMammalia%2CReptilia%2Cunknown&id_above=141745559&q=roadkill&page=1&per_page=200&order=asc&order_by=id (Caused by NameResolutionError("<urllib3.connection.HTTPSConnection object at 0xffff8b5204d0>: Failed to resolve 'api.inaturalist.org' ([Errno -3] Temporary failure in name resolution)"))

During handling of the above exception, another exception occurred:

Traceback (most recent call last):
  File "/home/airflow/.local/lib/python3.12/site-packages/airflow/models/taskinstance.py", line 767, in _execute_task
    result = _execute_callable(context=context, **execute_callable_kwargs)
             ^^^^^^^^^^^^^^^^^^^^^^^^^^^^^^^^^^^^^^^^^^^^^^^^^^^^^^^^^^^^^
  File "/home/airflow/.local/lib/python3.12/site-packages/airflow/models/taskinstance.py", line 733, in _execute_callable
    return ExecutionCallableRunner(
           ^^^^^^^^^^^^^^^^^^^^^^^^
  File "/home/airflow/.local/lib/python3.12/site-packages/airflow/utils/operator_helpers.py", line 252, in run
    return self.func(*args, **kwargs)
           ^^^^^^^^^^^^^^^^^^^^^^^^^^
  File "/home/airflow/.local/lib/python3.12/site-packages/airflow/models/baseoperator.py", line 406, in wrapper
    return func(self, *args, **kwargs)
           ^^^^^^^^^^^^^^^^^^^^^^^^^^^
  File "/home/airflow/.local/lib/python3.12/site-packages/airflow/decorators/base.py", line 266, in execute
    return_value = super().execute(context)
                   ^^^^^^^^^^^^^^^^^^^^^^^^
  File "/home/airflow/.local/lib/python3.12/site-packages/airflow/models/baseoperator.py", line 406, in wrapper
    return func(self, *args, **kwargs)
           ^^^^^^^^^^^^^^^^^^^^^^^^^^^
  File "/home/airflow/.local/lib/python3.12/site-packages/airflow/operators/python.py", line 238, in execute
    return_value = self.execute_callable()
                   ^^^^^^^^^^^^^^^^^^^^^^^
  File "/home/airflow/.local/lib/python3.12/site-packages/airflow/operators/python.py", line 256, in execute_callable
    return runner.run(*self.op_args, **self.op_kwargs)
           ^^^^^^^^^^^^^^^^^^^^^^^^^^^^^^^^^^^^^^^^^^^
  File "/home/airflow/.local/lib/python3.12/site-packages/airflow/utils/operator_helpers.py", line 252, in run
    return self.func(*args, **kwargs)
           ^^^^^^^^^^^^^^^^^^^^^^^^^^
  File "/opt/airflow/dags/inaturalist_dag.py", line 155, in get_all_data
    last_observation_id, observations_extracted = get_data(maximum_id, api_url)
                                                  ^^^^^^^^^^^^^^^^^^^^^^^^^^^^^
  File "/opt/airflow/dags/inaturalist_dag.py", line 53, in get_data
    response = requests.get(api_url, params=params)
               ^^^^^^^^^^^^^^^^^^^^^^^^^^^^^^^^^^^^
  File "/home/airflow/.local/lib/python3.12/site-packages/requests/api.py", line 73, in get
    return request("get", url, params=params, **kwargs)
           ^^^^^^^^^^^^^^^^^^^^^^^^^^^^^^^^^^^^^^^^^^^^
  File "/home/airflow/.local/lib/python3.12/site-packages/requests/api.py", line 59, in request
    return session.request(method=method, url=url, **kwargs)
           ^^^^^^^^^^^^^^^^^^^^^^^^^^^^^^^^^^^^^^^^^^^^^^^^^
  File "/home/airflow/.local/lib/python3.12/site-packages/requests/sessions.py", line 589, in request
    resp = self.send(prep, **send_kwargs)
           ^^^^^^^^^^^^^^^^^^^^^^^^^^^^^^
  File "/home/airflow/.local/lib/python3.12/site-packages/requests/sessions.py", line 703, in send
    r = adapter.send(request, **kwargs)
        ^^^^^^^^^^^^^^^^^^^^^^^^^^^^^^^
  File "/home/airflow/.local/lib/python3.12/site-packages/requests/adapters.py", line 700, in send
    raise ConnectionError(e, request=request)
requests.exceptions.ConnectionError: HTTPSConnectionPool(host='api.inaturalist.org', port=443): Max retries exceeded with url: /v1/observations?geo=true&iconic_taxa=Amphibia%2CAves%2CMammalia%2CReptilia%2Cunknown&id_above=141745559&q=roadkill&page=1&per_page=200&order=asc&order_by=id (Caused by NameResolutionError("<urllib3.connection.HTTPSConnection object at 0xffff8b5204d0>: Failed to resolve 'api.inaturalist.org' ([Errno -3] Temporary failure in name resolution)"))
[2025-03-25T22:32:51.734+0000] {taskinstance.py:1225} INFO - Marking task as UP_FOR_RETRY. dag_id=get_inaturalist_data_roadkill, task_id=get_all_data, run_id=scheduled__2025-03-25T22:00:00+00:00, execution_date=20250325T220000, start_date=20250325T223010, end_date=20250325T223251
[2025-03-25T22:32:52.133+0000] {taskinstance.py:340} INFO - ::group::Post task execution logs
[2025-03-25T22:32:52.157+0000] {standard_task_runner.py:124} ERROR - Failed to execute job 118 for task get_all_data (HTTPSConnectionPool(host='api.inaturalist.org', port=443): Max retries exceeded with url: /v1/observations?geo=true&iconic_taxa=Amphibia%2CAves%2CMammalia%2CReptilia%2Cunknown&id_above=141745559&q=roadkill&page=1&per_page=200&order=asc&order_by=id (Caused by NameResolutionError("<urllib3.connection.HTTPSConnection object at 0xffff8b5204d0>: Failed to resolve 'api.inaturalist.org' ([Errno -3] Temporary failure in name resolution)")); 1790)
Traceback (most recent call last):
  File "/home/airflow/.local/lib/python3.12/site-packages/urllib3/connection.py", line 196, in _new_conn
    sock = connection.create_connection(
           ^^^^^^^^^^^^^^^^^^^^^^^^^^^^^
  File "/home/airflow/.local/lib/python3.12/site-packages/urllib3/util/connection.py", line 60, in create_connection
    for res in socket.getaddrinfo(host, port, family, socket.SOCK_STREAM):
               ^^^^^^^^^^^^^^^^^^^^^^^^^^^^^^^^^^^^^^^^^^^^^^^^^^^^^^^^^^
  File "/usr/local/lib/python3.12/socket.py", line 976, in getaddrinfo
    for res in _socket.getaddrinfo(host, port, family, type, proto, flags):
               ^^^^^^^^^^^^^^^^^^^^^^^^^^^^^^^^^^^^^^^^^^^^^^^^^^^^^^^^^^^
socket.gaierror: [Errno -3] Temporary failure in name resolution

The above exception was the direct cause of the following exception:

Traceback (most recent call last):
  File "/home/airflow/.local/lib/python3.12/site-packages/urllib3/connectionpool.py", line 789, in urlopen
    response = self._make_request(
               ^^^^^^^^^^^^^^^^^^^
  File "/home/airflow/.local/lib/python3.12/site-packages/urllib3/connectionpool.py", line 490, in _make_request
    raise new_e
  File "/home/airflow/.local/lib/python3.12/site-packages/urllib3/connectionpool.py", line 466, in _make_request
    self._validate_conn(conn)
  File "/home/airflow/.local/lib/python3.12/site-packages/urllib3/connectionpool.py", line 1095, in _validate_conn
    conn.connect()
  File "/home/airflow/.local/lib/python3.12/site-packages/urllib3/connection.py", line 615, in connect
    self.sock = sock = self._new_conn()
                       ^^^^^^^^^^^^^^^^
  File "/home/airflow/.local/lib/python3.12/site-packages/urllib3/connection.py", line 203, in _new_conn
    raise NameResolutionError(self.host, self, e) from e
urllib3.exceptions.NameResolutionError: <urllib3.connection.HTTPSConnection object at 0xffff8b5204d0>: Failed to resolve 'api.inaturalist.org' ([Errno -3] Temporary failure in name resolution)

The above exception was the direct cause of the following exception:

Traceback (most recent call last):
  File "/home/airflow/.local/lib/python3.12/site-packages/requests/adapters.py", line 667, in send
    resp = conn.urlopen(
           ^^^^^^^^^^^^^
  File "/home/airflow/.local/lib/python3.12/site-packages/urllib3/connectionpool.py", line 843, in urlopen
    retries = retries.increment(
              ^^^^^^^^^^^^^^^^^^
  File "/home/airflow/.local/lib/python3.12/site-packages/urllib3/util/retry.py", line 519, in increment
    raise MaxRetryError(_pool, url, reason) from reason  # type: ignore[arg-type]
    ^^^^^^^^^^^^^^^^^^^^^^^^^^^^^^^^^^^^^^^^^^^^^^^^^^^
urllib3.exceptions.MaxRetryError: HTTPSConnectionPool(host='api.inaturalist.org', port=443): Max retries exceeded with url: /v1/observations?geo=true&iconic_taxa=Amphibia%2CAves%2CMammalia%2CReptilia%2Cunknown&id_above=141745559&q=roadkill&page=1&per_page=200&order=asc&order_by=id (Caused by NameResolutionError("<urllib3.connection.HTTPSConnection object at 0xffff8b5204d0>: Failed to resolve 'api.inaturalist.org' ([Errno -3] Temporary failure in name resolution)"))

During handling of the above exception, another exception occurred:

Traceback (most recent call last):
  File "/home/airflow/.local/lib/python3.12/site-packages/airflow/task/task_runner/standard_task_runner.py", line 117, in _start_by_fork
    ret = args.func(args, dag=self.dag)
          ^^^^^^^^^^^^^^^^^^^^^^^^^^^^^
  File "/home/airflow/.local/lib/python3.12/site-packages/airflow/cli/cli_config.py", line 49, in command
    return func(*args, **kwargs)
           ^^^^^^^^^^^^^^^^^^^^^
  File "/home/airflow/.local/lib/python3.12/site-packages/airflow/utils/cli.py", line 115, in wrapper
    return f(*args, **kwargs)
           ^^^^^^^^^^^^^^^^^^
  File "/home/airflow/.local/lib/python3.12/site-packages/airflow/cli/commands/task_command.py", line 483, in task_run
    task_return_code = _run_task_by_selected_method(args, _dag, ti)
                       ^^^^^^^^^^^^^^^^^^^^^^^^^^^^^^^^^^^^^^^^^^^^
  File "/home/airflow/.local/lib/python3.12/site-packages/airflow/cli/commands/task_command.py", line 256, in _run_task_by_selected_method
    return _run_raw_task(args, ti)
           ^^^^^^^^^^^^^^^^^^^^^^^
  File "/home/airflow/.local/lib/python3.12/site-packages/airflow/cli/commands/task_command.py", line 341, in _run_raw_task
    return ti._run_raw_task(
           ^^^^^^^^^^^^^^^^^
  File "/home/airflow/.local/lib/python3.12/site-packages/airflow/utils/session.py", line 97, in wrapper
    return func(*args, session=session, **kwargs)
           ^^^^^^^^^^^^^^^^^^^^^^^^^^^^^^^^^^^^^^
  File "/home/airflow/.local/lib/python3.12/site-packages/airflow/models/taskinstance.py", line 3004, in _run_raw_task
    return _run_raw_task(
           ^^^^^^^^^^^^^^
  File "/home/airflow/.local/lib/python3.12/site-packages/airflow/models/taskinstance.py", line 273, in _run_raw_task
    TaskInstance._execute_task_with_callbacks(
  File "/home/airflow/.local/lib/python3.12/site-packages/airflow/models/taskinstance.py", line 3158, in _execute_task_with_callbacks
    result = self._execute_task(context, task_orig)
             ^^^^^^^^^^^^^^^^^^^^^^^^^^^^^^^^^^^^^^
  File "/home/airflow/.local/lib/python3.12/site-packages/airflow/models/taskinstance.py", line 3182, in _execute_task
    return _execute_task(self, context, task_orig)
           ^^^^^^^^^^^^^^^^^^^^^^^^^^^^^^^^^^^^^^^
  File "/home/airflow/.local/lib/python3.12/site-packages/airflow/models/taskinstance.py", line 767, in _execute_task
    result = _execute_callable(context=context, **execute_callable_kwargs)
             ^^^^^^^^^^^^^^^^^^^^^^^^^^^^^^^^^^^^^^^^^^^^^^^^^^^^^^^^^^^^^
  File "/home/airflow/.local/lib/python3.12/site-packages/airflow/models/taskinstance.py", line 733, in _execute_callable
    return ExecutionCallableRunner(
           ^^^^^^^^^^^^^^^^^^^^^^^^
  File "/home/airflow/.local/lib/python3.12/site-packages/airflow/utils/operator_helpers.py", line 252, in run
    return self.func(*args, **kwargs)
           ^^^^^^^^^^^^^^^^^^^^^^^^^^
  File "/home/airflow/.local/lib/python3.12/site-packages/airflow/models/baseoperator.py", line 406, in wrapper
    return func(self, *args, **kwargs)
           ^^^^^^^^^^^^^^^^^^^^^^^^^^^
  File "/home/airflow/.local/lib/python3.12/site-packages/airflow/decorators/base.py", line 266, in execute
    return_value = super().execute(context)
                   ^^^^^^^^^^^^^^^^^^^^^^^^
  File "/home/airflow/.local/lib/python3.12/site-packages/airflow/models/baseoperator.py", line 406, in wrapper
    return func(self, *args, **kwargs)
           ^^^^^^^^^^^^^^^^^^^^^^^^^^^
  File "/home/airflow/.local/lib/python3.12/site-packages/airflow/operators/python.py", line 238, in execute
    return_value = self.execute_callable()
                   ^^^^^^^^^^^^^^^^^^^^^^^
  File "/home/airflow/.local/lib/python3.12/site-packages/airflow/operators/python.py", line 256, in execute_callable
    return runner.run(*self.op_args, **self.op_kwargs)
           ^^^^^^^^^^^^^^^^^^^^^^^^^^^^^^^^^^^^^^^^^^^
  File "/home/airflow/.local/lib/python3.12/site-packages/airflow/utils/operator_helpers.py", line 252, in run
    return self.func(*args, **kwargs)
           ^^^^^^^^^^^^^^^^^^^^^^^^^^
  File "/opt/airflow/dags/inaturalist_dag.py", line 155, in get_all_data
    last_observation_id, observations_extracted = get_data(maximum_id, api_url)
                                                  ^^^^^^^^^^^^^^^^^^^^^^^^^^^^^
  File "/opt/airflow/dags/inaturalist_dag.py", line 53, in get_data
    response = requests.get(api_url, params=params)
               ^^^^^^^^^^^^^^^^^^^^^^^^^^^^^^^^^^^^
  File "/home/airflow/.local/lib/python3.12/site-packages/requests/api.py", line 73, in get
    return request("get", url, params=params, **kwargs)
           ^^^^^^^^^^^^^^^^^^^^^^^^^^^^^^^^^^^^^^^^^^^^
  File "/home/airflow/.local/lib/python3.12/site-packages/requests/api.py", line 59, in request
    return session.request(method=method, url=url, **kwargs)
           ^^^^^^^^^^^^^^^^^^^^^^^^^^^^^^^^^^^^^^^^^^^^^^^^^
  File "/home/airflow/.local/lib/python3.12/site-packages/requests/sessions.py", line 589, in request
    resp = self.send(prep, **send_kwargs)
           ^^^^^^^^^^^^^^^^^^^^^^^^^^^^^^
  File "/home/airflow/.local/lib/python3.12/site-packages/requests/sessions.py", line 703, in send
    r = adapter.send(request, **kwargs)
        ^^^^^^^^^^^^^^^^^^^^^^^^^^^^^^^
  File "/home/airflow/.local/lib/python3.12/site-packages/requests/adapters.py", line 700, in send
    raise ConnectionError(e, request=request)
requests.exceptions.ConnectionError: HTTPSConnectionPool(host='api.inaturalist.org', port=443): Max retries exceeded with url: /v1/observations?geo=true&iconic_taxa=Amphibia%2CAves%2CMammalia%2CReptilia%2Cunknown&id_above=141745559&q=roadkill&page=1&per_page=200&order=asc&order_by=id (Caused by NameResolutionError("<urllib3.connection.HTTPSConnection object at 0xffff8b5204d0>: Failed to resolve 'api.inaturalist.org' ([Errno -3] Temporary failure in name resolution)"))
[2025-03-25T22:32:52.533+0000] {local_task_job_runner.py:266} INFO - Task exited with return code 1
[2025-03-25T22:32:53.188+0000] {taskinstance.py:3900} INFO - 0 downstream tasks scheduled from follow-on schedule check
[2025-03-25T22:32:53.231+0000] {local_task_job_runner.py:245} INFO - ::endgroup::
