[2025-03-27T12:42:56.088+0000] {local_task_job_runner.py:123} INFO - ::group::Pre task execution logs
[2025-03-27T12:42:56.119+0000] {taskinstance.py:2612} INFO - Dependencies all met for dep_context=non-requeueable deps ti=<TaskInstance: get_inaturalist_data_roadkill.get_all_data scheduled__2025-03-27T12:00:00+00:00 [queued]>
[2025-03-27T12:42:56.129+0000] {taskinstance.py:2612} INFO - Dependencies all met for dep_context=requeueable deps ti=<TaskInstance: get_inaturalist_data_roadkill.get_all_data scheduled__2025-03-27T12:00:00+00:00 [queued]>
[2025-03-27T12:42:56.130+0000] {taskinstance.py:2865} INFO - Starting attempt 1 of 4
[2025-03-27T12:42:56.151+0000] {taskinstance.py:2888} INFO - Executing <Task(_PythonDecoratedOperator): get_all_data> on 2025-03-27 12:00:00+00:00
[2025-03-27T12:42:56.164+0000] {warnings.py:112} WARNING - /home/***/.local/lib/python3.12/site-packages/***/task/task_runner/standard_task_runner.py:70: DeprecationWarning: This process (pid=57) is multi-threaded, use of fork() may lead to deadlocks in the child.
  pid = os.fork()

[2025-03-27T12:42:56.168+0000] {standard_task_runner.py:72} INFO - Started process 73 to run task
[2025-03-27T12:42:56.166+0000] {standard_task_runner.py:104} INFO - Running: ['***', 'tasks', 'run', 'get_inaturalist_data_roadkill', 'get_all_data', 'scheduled__2025-03-27T12:00:00+00:00', '--job-id', '48', '--raw', '--subdir', 'DAGS_FOLDER/inaturalist_dag.py', '--cfg-path', '/tmp/tmpf2y7kyhv']
[2025-03-27T12:42:56.170+0000] {standard_task_runner.py:105} INFO - Job 48: Subtask get_all_data
[2025-03-27T12:42:56.268+0000] {task_command.py:467} INFO - Running <TaskInstance: get_inaturalist_data_roadkill.get_all_data scheduled__2025-03-27T12:00:00+00:00 [running]> on host 2dfc7d159e9f
[2025-03-27T12:42:56.359+0000] {taskinstance.py:3131} INFO - Exporting env vars: AIRFLOW_CTX_DAG_OWNER='***' AIRFLOW_CTX_DAG_ID='get_inaturalist_data_roadkill' AIRFLOW_CTX_TASK_ID='get_all_data' AIRFLOW_CTX_EXECUTION_DATE='2025-03-27T12:00:00+00:00' AIRFLOW_CTX_TRY_NUMBER='1' AIRFLOW_CTX_DAG_RUN_ID='scheduled__2025-03-27T12:00:00+00:00'
[2025-03-27T12:42:56.360+0000] {taskinstance.py:731} INFO - ::endgroup::
[2025-03-27T12:42:56.367+0000] {inaturalist_dag.py:150} INFO - Getting data from keyword: roadkill
[2025-03-27T12:42:56.381+0000] {inaturalist_dag.py:41} INFO - Maximum id 21439887 for the request
[2025-03-27T12:42:59.472+0000] {inaturalist_dag.py:58} INFO - Got 200 results
[2025-03-27T12:42:59.521+0000] {inaturalist_dag.py:163} INFO - Extracted 200 observations
[2025-03-27T12:42:59.521+0000] {inaturalist_dag.py:41} INFO - Maximum id 21448292 for the request
[2025-03-27T12:43:04.776+0000] {inaturalist_dag.py:58} INFO - Got 200 results
[2025-03-27T12:43:04.784+0000] {inaturalist_dag.py:163} INFO - Extracted 400 observations
[2025-03-27T12:43:04.785+0000] {inaturalist_dag.py:41} INFO - Maximum id 21575526 for the request
[2025-03-27T12:43:07.966+0000] {inaturalist_dag.py:58} INFO - Got 200 results
[2025-03-27T12:43:07.975+0000] {inaturalist_dag.py:163} INFO - Extracted 600 observations
[2025-03-27T12:43:07.975+0000] {inaturalist_dag.py:41} INFO - Maximum id 21800619 for the request
[2025-03-27T12:43:14.748+0000] {inaturalist_dag.py:58} INFO - Got 200 results
[2025-03-27T12:43:14.765+0000] {inaturalist_dag.py:163} INFO - Extracted 795 observations
[2025-03-27T12:43:14.766+0000] {inaturalist_dag.py:41} INFO - Maximum id 24471089 for the request
[2025-03-27T12:43:20.543+0000] {inaturalist_dag.py:58} INFO - Got 200 results
[2025-03-27T12:43:20.561+0000] {inaturalist_dag.py:163} INFO - Extracted 993 observations
[2025-03-27T12:43:20.561+0000] {inaturalist_dag.py:41} INFO - Maximum id 26505152 for the request
[2025-03-27T12:44:22.748+0000] {job.py:239} ERROR - Job heartbeat failed with error
Traceback (most recent call last):
  File "/home/airflow/.local/lib/python3.12/site-packages/sqlalchemy/engine/base.py", line 3371, in _wrap_pool_connect
  File "/home/airflow/.local/lib/python3.12/site-packages/sqlalchemy/pool/base.py", line 327, in connect
  File "/home/airflow/.local/lib/python3.12/site-packages/sqlalchemy/pool/base.py", line 894, in _checkout
  File "/home/airflow/.local/lib/python3.12/site-packages/sqlalchemy/pool/base.py", line 493, in checkout
  File "/home/airflow/.local/lib/python3.12/site-packages/sqlalchemy/pool/impl.py", line 256, in _do_get
  File "/home/airflow/.local/lib/python3.12/site-packages/sqlalchemy/pool/base.py", line 273, in _create_connection
  File "/home/airflow/.local/lib/python3.12/site-packages/sqlalchemy/pool/base.py", line 388, in __init__
  File "/home/airflow/.local/lib/python3.12/site-packages/sqlalchemy/pool/base.py", line 690, in __connect
  File "/home/airflow/.local/lib/python3.12/site-packages/sqlalchemy/util/langhelpers.py", line 70, in __exit__
  File "/home/airflow/.local/lib/python3.12/site-packages/sqlalchemy/util/compat.py", line 211, in raise_
  File "/home/airflow/.local/lib/python3.12/site-packages/sqlalchemy/pool/base.py", line 686, in __connect
  File "/home/airflow/.local/lib/python3.12/site-packages/sqlalchemy/engine/create.py", line 574, in connect
  File "/home/airflow/.local/lib/python3.12/site-packages/sqlalchemy/engine/default.py", line 598, in connect
  File "/home/airflow/.local/lib/python3.12/site-packages/psycopg2/__init__.py", line 122, in connect
psycopg2.OperationalError: connection to server at "postgres" (172.20.0.6), port 5432 failed: No route to host
	Is the server running on that host and accepting TCP/IP connections?


The above exception was the direct cause of the following exception:

Traceback (most recent call last):
  File "/home/airflow/.local/lib/python3.12/site-packages/airflow/jobs/job.py", line 224, in heartbeat
  File "/home/airflow/.local/lib/python3.12/site-packages/airflow/api_internal/internal_api_call.py", line 139, in wrapper
  File "/home/airflow/.local/lib/python3.12/site-packages/airflow/utils/session.py", line 94, in wrapper
  File "/home/airflow/.local/lib/python3.12/site-packages/airflow/utils/retries.py", line 93, in wrapped_function
  File "/home/airflow/.local/lib/python3.12/site-packages/tenacity/__init__.py", line 443, in __iter__
  File "/home/airflow/.local/lib/python3.12/site-packages/tenacity/__init__.py", line 376, in iter
  File "/home/airflow/.local/lib/python3.12/site-packages/tenacity/__init__.py", line 418, in exc_check
  File "/home/airflow/.local/lib/python3.12/site-packages/tenacity/__init__.py", line 185, in reraise
  File "/usr/local/lib/python3.12/concurrent/futures/_base.py", line 449, in result
  File "/usr/local/lib/python3.12/concurrent/futures/_base.py", line 401, in __get_result
  File "/home/airflow/.local/lib/python3.12/site-packages/airflow/utils/retries.py", line 102, in wrapped_function
  File "/home/airflow/.local/lib/python3.12/site-packages/airflow/jobs/job.py", line 374, in _update_heartbeat
  File "/home/airflow/.local/lib/python3.12/site-packages/sqlalchemy/orm/session.py", line 1747, in scalar
  File "/home/airflow/.local/lib/python3.12/site-packages/sqlalchemy/orm/session.py", line 1716, in execute
  File "/home/airflow/.local/lib/python3.12/site-packages/sqlalchemy/orm/session.py", line 1555, in _connection_for_bind
  File "/home/airflow/.local/lib/python3.12/site-packages/sqlalchemy/orm/session.py", line 750, in _connection_for_bind
  File "/home/airflow/.local/lib/python3.12/site-packages/sqlalchemy/future/engine.py", line 412, in connect
  File "/home/airflow/.local/lib/python3.12/site-packages/sqlalchemy/engine/base.py", line 3325, in connect
  File "/home/airflow/.local/lib/python3.12/site-packages/sqlalchemy/engine/base.py", line 96, in __init__
  File "/home/airflow/.local/lib/python3.12/site-packages/sqlalchemy/engine/base.py", line 3404, in raw_connection
  File "/home/airflow/.local/lib/python3.12/site-packages/sqlalchemy/engine/base.py", line 3374, in _wrap_pool_connect
  File "/home/airflow/.local/lib/python3.12/site-packages/sqlalchemy/engine/base.py", line 2208, in _handle_dbapi_exception_noconnection
  File "/home/airflow/.local/lib/python3.12/site-packages/sqlalchemy/util/compat.py", line 211, in raise_
  File "/home/airflow/.local/lib/python3.12/site-packages/sqlalchemy/engine/base.py", line 3371, in _wrap_pool_connect
  File "/home/airflow/.local/lib/python3.12/site-packages/sqlalchemy/pool/base.py", line 327, in connect
  File "/home/airflow/.local/lib/python3.12/site-packages/sqlalchemy/pool/base.py", line 894, in _checkout
  File "/home/airflow/.local/lib/python3.12/site-packages/sqlalchemy/pool/base.py", line 493, in checkout
  File "/home/airflow/.local/lib/python3.12/site-packages/sqlalchemy/pool/impl.py", line 256, in _do_get
  File "/home/airflow/.local/lib/python3.12/site-packages/sqlalchemy/pool/base.py", line 273, in _create_connection
  File "/home/airflow/.local/lib/python3.12/site-packages/sqlalchemy/pool/base.py", line 388, in __init__
  File "/home/airflow/.local/lib/python3.12/site-packages/sqlalchemy/pool/base.py", line 690, in __connect
  File "/home/airflow/.local/lib/python3.12/site-packages/sqlalchemy/util/langhelpers.py", line 70, in __exit__
  File "/home/airflow/.local/lib/python3.12/site-packages/sqlalchemy/util/compat.py", line 211, in raise_
  File "/home/airflow/.local/lib/python3.12/site-packages/sqlalchemy/pool/base.py", line 686, in __connect
  File "/home/airflow/.local/lib/python3.12/site-packages/sqlalchemy/engine/create.py", line 574, in connect
  File "/home/airflow/.local/lib/python3.12/site-packages/sqlalchemy/engine/default.py", line 598, in connect
  File "/home/airflow/.local/lib/python3.12/site-packages/psycopg2/__init__.py", line 122, in connect
sqlalchemy.exc.OperationalError: (psycopg2.OperationalError) connection to server at "postgres" (172.20.0.6), port 5432 failed: No route to host
	Is the server running on that host and accepting TCP/IP connections?

(Background on this error at: https://sqlalche.me/e/14/e3q8)
[2025-03-27T12:44:22.777+0000] {job.py:254} ERROR - Job heartbeat failed with error. Scheduler is in unhealthy state
[2025-03-27T12:44:37.901+0000] {job.py:254} ERROR - Job heartbeat failed with error. Scheduler is in unhealthy state
[2025-03-27T12:44:52.362+0000] {job.py:254} ERROR - Job heartbeat failed with error. Scheduler is in unhealthy state
[2025-03-27T12:45:06.888+0000] {job.py:254} ERROR - Job heartbeat failed with error. Scheduler is in unhealthy state
[2025-03-27T12:45:21.924+0000] {job.py:254} ERROR - Job heartbeat failed with error. Scheduler is in unhealthy state
[2025-03-27T12:45:35.953+0000] {taskinstance.py:3310} ERROR - Task failed with exception
Traceback (most recent call last):
  File "/home/airflow/.local/lib/python3.12/site-packages/urllib3/connection.py", line 196, in _new_conn
  File "/home/airflow/.local/lib/python3.12/site-packages/urllib3/util/connection.py", line 85, in create_connection
  File "/home/airflow/.local/lib/python3.12/site-packages/urllib3/util/connection.py", line 73, in create_connection
TimeoutError: [Errno 110] Connection timed out

The above exception was the direct cause of the following exception:

Traceback (most recent call last):
  File "/home/airflow/.local/lib/python3.12/site-packages/urllib3/connectionpool.py", line 789, in urlopen
  File "/home/airflow/.local/lib/python3.12/site-packages/urllib3/connectionpool.py", line 490, in _make_request
  File "/home/airflow/.local/lib/python3.12/site-packages/urllib3/connectionpool.py", line 466, in _make_request
  File "/home/airflow/.local/lib/python3.12/site-packages/urllib3/connectionpool.py", line 1095, in _validate_conn
  File "/home/airflow/.local/lib/python3.12/site-packages/urllib3/connection.py", line 615, in connect
  File "/home/airflow/.local/lib/python3.12/site-packages/urllib3/connection.py", line 205, in _new_conn
urllib3.exceptions.ConnectTimeoutError: (<urllib3.connection.HTTPSConnection object at 0xffff851fc620>, 'Connection to api.inaturalist.org timed out. (connect timeout=None)')

The above exception was the direct cause of the following exception:

Traceback (most recent call last):
  File "/home/airflow/.local/lib/python3.12/site-packages/requests/adapters.py", line 667, in send
  File "/home/airflow/.local/lib/python3.12/site-packages/urllib3/connectionpool.py", line 843, in urlopen
  File "/home/airflow/.local/lib/python3.12/site-packages/urllib3/util/retry.py", line 519, in increment
urllib3.exceptions.MaxRetryError: HTTPSConnectionPool(host='api.inaturalist.org', port=443): Max retries exceeded with url: /v1/observations?geo=true&iconic_taxa=Amphibia%2CAves%2CMammalia%2CReptilia%2Cunknown&id_above=26505152&q=roadkill&page=1&per_page=200&order=asc&order_by=id (Caused by ConnectTimeoutError(<urllib3.connection.HTTPSConnection object at 0xffff851fc620>, 'Connection to api.inaturalist.org timed out. (connect timeout=None)'))

During handling of the above exception, another exception occurred:

Traceback (most recent call last):
  File "/home/airflow/.local/lib/python3.12/site-packages/airflow/models/taskinstance.py", line 767, in _execute_task
    result = _execute_callable(context=context, **execute_callable_kwargs)
             ^^^^^^^^^^^^^^^^^^^^^^^^^^^^^^^^^^^^^^^^^^^^^^^^^^^^^^^^^^^^^
  File "/home/airflow/.local/lib/python3.12/site-packages/airflow/models/taskinstance.py", line 733, in _execute_callable
    return ExecutionCallableRunner(
           ^^^^^^^^^^^^^^^^^^^^^^^^
  File "/home/airflow/.local/lib/python3.12/site-packages/airflow/utils/operator_helpers.py", line 252, in run
  File "/home/airflow/.local/lib/python3.12/site-packages/airflow/models/baseoperator.py", line 406, in wrapper
  File "/home/airflow/.local/lib/python3.12/site-packages/airflow/decorators/base.py", line 266, in execute
  File "/home/airflow/.local/lib/python3.12/site-packages/airflow/models/baseoperator.py", line 406, in wrapper
  File "/home/airflow/.local/lib/python3.12/site-packages/airflow/operators/python.py", line 238, in execute
  File "/home/airflow/.local/lib/python3.12/site-packages/airflow/operators/python.py", line 256, in execute_callable
  File "/home/airflow/.local/lib/python3.12/site-packages/airflow/utils/operator_helpers.py", line 252, in run
  File "/opt/airflow/dags/inaturalist_dag.py", line 155, in get_all_data
    last_observation_id, observations_extracted = get_data(maximum_id, api_url)
                                                  ^^^^^^^^^^^^^^^^^^^^^^^^^^^^^
  File "/opt/airflow/dags/inaturalist_dag.py", line 53, in get_data
    response = requests.get(api_url, params=params)
               ^^^^^^^^^^^^^^^^^^^^^^^^^^^^^^^^^^^^
  File "/home/airflow/.local/lib/python3.12/site-packages/requests/api.py", line 73, in get
  File "/home/airflow/.local/lib/python3.12/site-packages/requests/api.py", line 59, in request
  File "/home/airflow/.local/lib/python3.12/site-packages/requests/sessions.py", line 589, in request
  File "/home/airflow/.local/lib/python3.12/site-packages/requests/sessions.py", line 703, in send
  File "/home/airflow/.local/lib/python3.12/site-packages/requests/adapters.py", line 688, in send
requests.exceptions.ConnectTimeout: HTTPSConnectionPool(host='api.inaturalist.org', port=443): Max retries exceeded with url: /v1/observations?geo=true&iconic_taxa=Amphibia%2CAves%2CMammalia%2CReptilia%2Cunknown&id_above=26505152&q=roadkill&page=1&per_page=200&order=asc&order_by=id (Caused by ConnectTimeoutError(<urllib3.connection.HTTPSConnection object at 0xffff851fc620>, 'Connection to api.inaturalist.org timed out. (connect timeout=None)'))
[2025-03-27T12:45:37.030+0000] {taskinstance.py:340} INFO - ::group::Post task execution logs
[2025-03-27T12:45:37.030+0000] {job.py:254} ERROR - Job heartbeat failed with error. Scheduler is in unhealthy state
[2025-03-27T12:45:37.035+0000] {standard_task_runner.py:124} ERROR - Failed to execute job 48 for task get_all_data ((psycopg2.OperationalError) connection to server at "postgres" (172.20.0.6), port 5432 failed: No route to host
	Is the server running on that host and accepting TCP/IP connections?

(Background on this error at: https://sqlalche.me/e/14/e3q8); 73)
Traceback (most recent call last):
  File "/home/airflow/.local/lib/python3.12/site-packages/urllib3/connection.py", line 196, in _new_conn
  File "/home/airflow/.local/lib/python3.12/site-packages/urllib3/util/connection.py", line 85, in create_connection
  File "/home/airflow/.local/lib/python3.12/site-packages/urllib3/util/connection.py", line 73, in create_connection
TimeoutError: [Errno 110] Connection timed out

The above exception was the direct cause of the following exception:

Traceback (most recent call last):
  File "/home/airflow/.local/lib/python3.12/site-packages/urllib3/connectionpool.py", line 789, in urlopen
  File "/home/airflow/.local/lib/python3.12/site-packages/urllib3/connectionpool.py", line 490, in _make_request
  File "/home/airflow/.local/lib/python3.12/site-packages/urllib3/connectionpool.py", line 466, in _make_request
  File "/home/airflow/.local/lib/python3.12/site-packages/urllib3/connectionpool.py", line 1095, in _validate_conn
  File "/home/airflow/.local/lib/python3.12/site-packages/urllib3/connection.py", line 615, in connect
  File "/home/airflow/.local/lib/python3.12/site-packages/urllib3/connection.py", line 205, in _new_conn
urllib3.exceptions.ConnectTimeoutError: (<urllib3.connection.HTTPSConnection object at 0xffff851fc620>, 'Connection to api.inaturalist.org timed out. (connect timeout=None)')

The above exception was the direct cause of the following exception:

Traceback (most recent call last):
  File "/home/airflow/.local/lib/python3.12/site-packages/requests/adapters.py", line 667, in send
  File "/home/airflow/.local/lib/python3.12/site-packages/urllib3/connectionpool.py", line 843, in urlopen
  File "/home/airflow/.local/lib/python3.12/site-packages/urllib3/util/retry.py", line 519, in increment
urllib3.exceptions.MaxRetryError: HTTPSConnectionPool(host='api.inaturalist.org', port=443): Max retries exceeded with url: /v1/observations?geo=true&iconic_taxa=Amphibia%2CAves%2CMammalia%2CReptilia%2Cunknown&id_above=26505152&q=roadkill&page=1&per_page=200&order=asc&order_by=id (Caused by ConnectTimeoutError(<urllib3.connection.HTTPSConnection object at 0xffff851fc620>, 'Connection to api.inaturalist.org timed out. (connect timeout=None)'))

During handling of the above exception, another exception occurred:

Traceback (most recent call last):
  File "/home/airflow/.local/lib/python3.12/site-packages/airflow/models/taskinstance.py", line 273, in _run_raw_task
    TaskInstance._execute_task_with_callbacks(
  File "/home/airflow/.local/lib/python3.12/site-packages/airflow/models/taskinstance.py", line 3158, in _execute_task_with_callbacks
    result = self._execute_task(context, task_orig)
             ^^^^^^^^^^^^^^^^^^^^^^^^^^^^^^^^^^^^^^
  File "/home/airflow/.local/lib/python3.12/site-packages/airflow/models/taskinstance.py", line 3182, in _execute_task
    return _execute_task(self, context, task_orig)
           ^^^^^^^^^^^^^^^^^^^^^^^^^^^^^^^^^^^^^^^
  File "/home/airflow/.local/lib/python3.12/site-packages/airflow/models/taskinstance.py", line 767, in _execute_task
    result = _execute_callable(context=context, **execute_callable_kwargs)
             ^^^^^^^^^^^^^^^^^^^^^^^^^^^^^^^^^^^^^^^^^^^^^^^^^^^^^^^^^^^^^
  File "/home/airflow/.local/lib/python3.12/site-packages/airflow/models/taskinstance.py", line 733, in _execute_callable
    return ExecutionCallableRunner(
           ^^^^^^^^^^^^^^^^^^^^^^^^
  File "/home/airflow/.local/lib/python3.12/site-packages/airflow/utils/operator_helpers.py", line 252, in run
  File "/home/airflow/.local/lib/python3.12/site-packages/airflow/models/baseoperator.py", line 406, in wrapper
  File "/home/airflow/.local/lib/python3.12/site-packages/airflow/decorators/base.py", line 266, in execute
  File "/home/airflow/.local/lib/python3.12/site-packages/airflow/models/baseoperator.py", line 406, in wrapper
  File "/home/airflow/.local/lib/python3.12/site-packages/airflow/operators/python.py", line 238, in execute
  File "/home/airflow/.local/lib/python3.12/site-packages/airflow/operators/python.py", line 256, in execute_callable
  File "/home/airflow/.local/lib/python3.12/site-packages/airflow/utils/operator_helpers.py", line 252, in run
  File "/opt/airflow/dags/inaturalist_dag.py", line 155, in get_all_data
    last_observation_id, observations_extracted = get_data(maximum_id, api_url)
                                                  ^^^^^^^^^^^^^^^^^^^^^^^^^^^^^
  File "/opt/airflow/dags/inaturalist_dag.py", line 53, in get_data
    response = requests.get(api_url, params=params)
               ^^^^^^^^^^^^^^^^^^^^^^^^^^^^^^^^^^^^
  File "/home/airflow/.local/lib/python3.12/site-packages/requests/api.py", line 73, in get
  File "/home/airflow/.local/lib/python3.12/site-packages/requests/api.py", line 59, in request
  File "/home/airflow/.local/lib/python3.12/site-packages/requests/sessions.py", line 589, in request
  File "/home/airflow/.local/lib/python3.12/site-packages/requests/sessions.py", line 703, in send
  File "/home/airflow/.local/lib/python3.12/site-packages/requests/adapters.py", line 688, in send
requests.exceptions.ConnectTimeout: HTTPSConnectionPool(host='api.inaturalist.org', port=443): Max retries exceeded with url: /v1/observations?geo=true&iconic_taxa=Amphibia%2CAves%2CMammalia%2CReptilia%2Cunknown&id_above=26505152&q=roadkill&page=1&per_page=200&order=asc&order_by=id (Caused by ConnectTimeoutError(<urllib3.connection.HTTPSConnection object at 0xffff851fc620>, 'Connection to api.inaturalist.org timed out. (connect timeout=None)'))

During handling of the above exception, another exception occurred:

Traceback (most recent call last):
  File "/home/airflow/.local/lib/python3.12/site-packages/sqlalchemy/engine/base.py", line 3371, in _wrap_pool_connect
  File "/home/airflow/.local/lib/python3.12/site-packages/sqlalchemy/pool/base.py", line 327, in connect
  File "/home/airflow/.local/lib/python3.12/site-packages/sqlalchemy/pool/base.py", line 894, in _checkout
  File "/home/airflow/.local/lib/python3.12/site-packages/sqlalchemy/pool/base.py", line 493, in checkout
  File "/home/airflow/.local/lib/python3.12/site-packages/sqlalchemy/pool/impl.py", line 256, in _do_get
  File "/home/airflow/.local/lib/python3.12/site-packages/sqlalchemy/pool/base.py", line 273, in _create_connection
  File "/home/airflow/.local/lib/python3.12/site-packages/sqlalchemy/pool/base.py", line 388, in __init__
  File "/home/airflow/.local/lib/python3.12/site-packages/sqlalchemy/pool/base.py", line 690, in __connect
  File "/home/airflow/.local/lib/python3.12/site-packages/sqlalchemy/util/langhelpers.py", line 70, in __exit__
  File "/home/airflow/.local/lib/python3.12/site-packages/sqlalchemy/util/compat.py", line 211, in raise_
  File "/home/airflow/.local/lib/python3.12/site-packages/sqlalchemy/pool/base.py", line 686, in __connect
  File "/home/airflow/.local/lib/python3.12/site-packages/sqlalchemy/engine/create.py", line 574, in connect
  File "/home/airflow/.local/lib/python3.12/site-packages/sqlalchemy/engine/default.py", line 598, in connect
  File "/home/airflow/.local/lib/python3.12/site-packages/psycopg2/__init__.py", line 122, in connect
psycopg2.OperationalError: connection to server at "postgres" (172.20.0.6), port 5432 failed: No route to host
	Is the server running on that host and accepting TCP/IP connections?


The above exception was the direct cause of the following exception:

Traceback (most recent call last):
  File "/home/airflow/.local/lib/python3.12/site-packages/airflow/task/task_runner/standard_task_runner.py", line 117, in _start_by_fork
  File "/home/airflow/.local/lib/python3.12/site-packages/airflow/cli/cli_config.py", line 49, in command
  File "/home/airflow/.local/lib/python3.12/site-packages/airflow/utils/cli.py", line 115, in wrapper
  File "/home/airflow/.local/lib/python3.12/site-packages/airflow/cli/commands/task_command.py", line 483, in task_run
  File "/home/airflow/.local/lib/python3.12/site-packages/airflow/cli/commands/task_command.py", line 256, in _run_task_by_selected_method
  File "/home/airflow/.local/lib/python3.12/site-packages/airflow/cli/commands/task_command.py", line 341, in _run_raw_task
  File "/home/airflow/.local/lib/python3.12/site-packages/airflow/utils/session.py", line 97, in wrapper
  File "/home/airflow/.local/lib/python3.12/site-packages/airflow/models/taskinstance.py", line 3004, in _run_raw_task
    return _run_raw_task(
           ^^^^^^^^^^^^^^
  File "/home/airflow/.local/lib/python3.12/site-packages/airflow/models/taskinstance.py", line 336, in _run_raw_task
    ti.handle_failure(e, test_mode, context, session=session)
  File "/home/airflow/.local/lib/python3.12/site-packages/airflow/utils/session.py", line 94, in wrapper
  File "/home/airflow/.local/lib/python3.12/site-packages/airflow/models/taskinstance.py", line 3427, in handle_failure
    _handle_failure(
  File "/home/airflow/.local/lib/python3.12/site-packages/airflow/utils/session.py", line 94, in wrapper
  File "/home/airflow/.local/lib/python3.12/site-packages/airflow/api_internal/internal_api_call.py", line 139, in wrapper
  File "/home/airflow/.local/lib/python3.12/site-packages/airflow/models/taskinstance.py", line 1215, in _handle_failure
    failure_context = TaskInstance.fetch_handle_failure_context(
                      ^^^^^^^^^^^^^^^^^^^^^^^^^^^^^^^^^^^^^^^^^^
  File "/home/airflow/.local/lib/python3.12/site-packages/airflow/models/taskinstance.py", line 3314, in fetch_handle_failure_context
    ti.refresh_from_db(session)
  File "/home/airflow/.local/lib/python3.12/site-packages/airflow/utils/session.py", line 94, in wrapper
  File "/home/airflow/.local/lib/python3.12/site-packages/airflow/models/taskinstance.py", line 2358, in refresh_from_db
    _refresh_from_db(task_instance=self, session=session, lock_for_update=lock_for_update)
  File "/home/airflow/.local/lib/python3.12/site-packages/airflow/models/taskinstance.py", line 872, in _refresh_from_db
    ti = TaskInstance.get_task_instance(
         ^^^^^^^^^^^^^^^^^^^^^^^^^^^^^^^
  File "/home/airflow/.local/lib/python3.12/site-packages/airflow/api_internal/internal_api_call.py", line 139, in wrapper
  File "/home/airflow/.local/lib/python3.12/site-packages/airflow/utils/session.py", line 94, in wrapper
  File "/home/airflow/.local/lib/python3.12/site-packages/airflow/models/taskinstance.py", line 2344, in get_task_instance
    return query.one_or_none()
           ^^^^^^^^^^^^^^^^^^^
  File "/home/airflow/.local/lib/python3.12/site-packages/sqlalchemy/orm/query.py", line 2850, in one_or_none
  File "/home/airflow/.local/lib/python3.12/site-packages/sqlalchemy/orm/query.py", line 2916, in _iter
  File "/home/airflow/.local/lib/python3.12/site-packages/sqlalchemy/orm/session.py", line 1716, in execute
  File "/home/airflow/.local/lib/python3.12/site-packages/sqlalchemy/orm/session.py", line 1555, in _connection_for_bind
  File "/home/airflow/.local/lib/python3.12/site-packages/sqlalchemy/orm/session.py", line 750, in _connection_for_bind
  File "/home/airflow/.local/lib/python3.12/site-packages/sqlalchemy/future/engine.py", line 412, in connect
  File "/home/airflow/.local/lib/python3.12/site-packages/sqlalchemy/engine/base.py", line 3325, in connect
  File "/home/airflow/.local/lib/python3.12/site-packages/sqlalchemy/engine/base.py", line 96, in __init__
  File "/home/airflow/.local/lib/python3.12/site-packages/sqlalchemy/engine/base.py", line 3404, in raw_connection
  File "/home/airflow/.local/lib/python3.12/site-packages/sqlalchemy/engine/base.py", line 3374, in _wrap_pool_connect
  File "/home/airflow/.local/lib/python3.12/site-packages/sqlalchemy/engine/base.py", line 2208, in _handle_dbapi_exception_noconnection
  File "/home/airflow/.local/lib/python3.12/site-packages/sqlalchemy/util/compat.py", line 211, in raise_
  File "/home/airflow/.local/lib/python3.12/site-packages/sqlalchemy/engine/base.py", line 3371, in _wrap_pool_connect
  File "/home/airflow/.local/lib/python3.12/site-packages/sqlalchemy/pool/base.py", line 327, in connect
  File "/home/airflow/.local/lib/python3.12/site-packages/sqlalchemy/pool/base.py", line 894, in _checkout
  File "/home/airflow/.local/lib/python3.12/site-packages/sqlalchemy/pool/base.py", line 493, in checkout
  File "/home/airflow/.local/lib/python3.12/site-packages/sqlalchemy/pool/impl.py", line 256, in _do_get
  File "/home/airflow/.local/lib/python3.12/site-packages/sqlalchemy/pool/base.py", line 273, in _create_connection
  File "/home/airflow/.local/lib/python3.12/site-packages/sqlalchemy/pool/base.py", line 388, in __init__
  File "/home/airflow/.local/lib/python3.12/site-packages/sqlalchemy/pool/base.py", line 690, in __connect
  File "/home/airflow/.local/lib/python3.12/site-packages/sqlalchemy/util/langhelpers.py", line 70, in __exit__
  File "/home/airflow/.local/lib/python3.12/site-packages/sqlalchemy/util/compat.py", line 211, in raise_
  File "/home/airflow/.local/lib/python3.12/site-packages/sqlalchemy/pool/base.py", line 686, in __connect
  File "/home/airflow/.local/lib/python3.12/site-packages/sqlalchemy/engine/create.py", line 574, in connect
  File "/home/airflow/.local/lib/python3.12/site-packages/sqlalchemy/engine/default.py", line 598, in connect
  File "/home/airflow/.local/lib/python3.12/site-packages/psycopg2/__init__.py", line 122, in connect
sqlalchemy.exc.OperationalError: (psycopg2.OperationalError) connection to server at "postgres" (172.20.0.6), port 5432 failed: No route to host
	Is the server running on that host and accepting TCP/IP connections?

(Background on this error at: https://sqlalche.me/e/14/e3q8)
[2025-03-27T12:45:37.095+0000] {local_task_job_runner.py:266} INFO - Task exited with return code 1
[2025-03-27T12:45:40.099+0000] {taskinstance.py:3906} WARNING - Skipping mini scheduling run due to exception: None
Traceback (most recent call last):
  File "/home/airflow/.local/lib/python3.12/site-packages/sqlalchemy/engine/base.py", line 3371, in _wrap_pool_connect
  File "/home/airflow/.local/lib/python3.12/site-packages/sqlalchemy/pool/base.py", line 327, in connect
  File "/home/airflow/.local/lib/python3.12/site-packages/sqlalchemy/pool/base.py", line 894, in _checkout
  File "/home/airflow/.local/lib/python3.12/site-packages/sqlalchemy/pool/base.py", line 493, in checkout
  File "/home/airflow/.local/lib/python3.12/site-packages/sqlalchemy/pool/impl.py", line 256, in _do_get
  File "/home/airflow/.local/lib/python3.12/site-packages/sqlalchemy/pool/base.py", line 273, in _create_connection
  File "/home/airflow/.local/lib/python3.12/site-packages/sqlalchemy/pool/base.py", line 388, in __init__
  File "/home/airflow/.local/lib/python3.12/site-packages/sqlalchemy/pool/base.py", line 690, in __connect
  File "/home/airflow/.local/lib/python3.12/site-packages/sqlalchemy/util/langhelpers.py", line 70, in __exit__
  File "/home/airflow/.local/lib/python3.12/site-packages/sqlalchemy/util/compat.py", line 211, in raise_
  File "/home/airflow/.local/lib/python3.12/site-packages/sqlalchemy/pool/base.py", line 686, in __connect
  File "/home/airflow/.local/lib/python3.12/site-packages/sqlalchemy/engine/create.py", line 574, in connect
  File "/home/airflow/.local/lib/python3.12/site-packages/sqlalchemy/engine/default.py", line 598, in connect
  File "/home/airflow/.local/lib/python3.12/site-packages/psycopg2/__init__.py", line 122, in connect
psycopg2.OperationalError: connection to server at "postgres" (172.20.0.6), port 5432 failed: No route to host
	Is the server running on that host and accepting TCP/IP connections?


The above exception was the direct cause of the following exception:

Traceback (most recent call last):
  File "/home/airflow/.local/lib/python3.12/site-packages/airflow/models/taskinstance.py", line 3855, in _schedule_downstream_tasks
    ).one_or_none()
      ^^^^^^^^^^^^^
  File "/home/airflow/.local/lib/python3.12/site-packages/sqlalchemy/orm/query.py", line 2850, in one_or_none
  File "/home/airflow/.local/lib/python3.12/site-packages/sqlalchemy/orm/query.py", line 2916, in _iter
  File "/home/airflow/.local/lib/python3.12/site-packages/sqlalchemy/orm/session.py", line 1716, in execute
  File "/home/airflow/.local/lib/python3.12/site-packages/sqlalchemy/orm/session.py", line 1555, in _connection_for_bind
  File "/home/airflow/.local/lib/python3.12/site-packages/sqlalchemy/orm/session.py", line 750, in _connection_for_bind
  File "/home/airflow/.local/lib/python3.12/site-packages/sqlalchemy/future/engine.py", line 412, in connect
  File "/home/airflow/.local/lib/python3.12/site-packages/sqlalchemy/engine/base.py", line 3325, in connect
  File "/home/airflow/.local/lib/python3.12/site-packages/sqlalchemy/engine/base.py", line 96, in __init__
  File "/home/airflow/.local/lib/python3.12/site-packages/sqlalchemy/engine/base.py", line 3404, in raw_connection
  File "/home/airflow/.local/lib/python3.12/site-packages/sqlalchemy/engine/base.py", line 3374, in _wrap_pool_connect
  File "/home/airflow/.local/lib/python3.12/site-packages/sqlalchemy/engine/base.py", line 2208, in _handle_dbapi_exception_noconnection
  File "/home/airflow/.local/lib/python3.12/site-packages/sqlalchemy/util/compat.py", line 211, in raise_
  File "/home/airflow/.local/lib/python3.12/site-packages/sqlalchemy/engine/base.py", line 3371, in _wrap_pool_connect
  File "/home/airflow/.local/lib/python3.12/site-packages/sqlalchemy/pool/base.py", line 327, in connect
  File "/home/airflow/.local/lib/python3.12/site-packages/sqlalchemy/pool/base.py", line 894, in _checkout
  File "/home/airflow/.local/lib/python3.12/site-packages/sqlalchemy/pool/base.py", line 493, in checkout
  File "/home/airflow/.local/lib/python3.12/site-packages/sqlalchemy/pool/impl.py", line 256, in _do_get
  File "/home/airflow/.local/lib/python3.12/site-packages/sqlalchemy/pool/base.py", line 273, in _create_connection
  File "/home/airflow/.local/lib/python3.12/site-packages/sqlalchemy/pool/base.py", line 388, in __init__
  File "/home/airflow/.local/lib/python3.12/site-packages/sqlalchemy/pool/base.py", line 690, in __connect
  File "/home/airflow/.local/lib/python3.12/site-packages/sqlalchemy/util/langhelpers.py", line 70, in __exit__
  File "/home/airflow/.local/lib/python3.12/site-packages/sqlalchemy/util/compat.py", line 211, in raise_
  File "/home/airflow/.local/lib/python3.12/site-packages/sqlalchemy/pool/base.py", line 686, in __connect
  File "/home/airflow/.local/lib/python3.12/site-packages/sqlalchemy/engine/create.py", line 574, in connect
  File "/home/airflow/.local/lib/python3.12/site-packages/sqlalchemy/engine/default.py", line 598, in connect
  File "/home/airflow/.local/lib/python3.12/site-packages/psycopg2/__init__.py", line 122, in connect
sqlalchemy.exc.OperationalError: (psycopg2.OperationalError) connection to server at "postgres" (172.20.0.6), port 5432 failed: No route to host
	Is the server running on that host and accepting TCP/IP connections?

(Background on this error at: https://sqlalche.me/e/14/e3q8)
[2025-03-27T12:45:40.110+0000] {local_task_job_runner.py:245} INFO - ::endgroup::
[2025-03-27T12:45:41.304+0000] {standard_task_runner.py:217} INFO - Process not found (most likely exited), stop collecting metrics
