[2025-03-26T18:27:46.380+0000] {local_task_job_runner.py:123} INFO - ::group::Pre task execution logs
[2025-03-26T18:27:46.575+0000] {taskinstance.py:2612} INFO - Dependencies all met for dep_context=non-requeueable deps ti=<TaskInstance: prf_dag.get_data scheduled__2025-02-01T00:00:00+00:00 [queued]>
[2025-03-26T18:27:46.638+0000] {taskinstance.py:2612} INFO - Dependencies all met for dep_context=requeueable deps ti=<TaskInstance: prf_dag.get_data scheduled__2025-02-01T00:00:00+00:00 [queued]>
[2025-03-26T18:27:46.639+0000] {taskinstance.py:2865} INFO - Starting attempt 2 of 4
[2025-03-26T18:27:46.712+0000] {taskinstance.py:2888} INFO - Executing <Task(_PythonDecoratedOperator): get_data> on 2025-02-01 00:00:00+00:00
[2025-03-26T18:27:46.769+0000] {standard_task_runner.py:104} INFO - Running: ['***', 'tasks', 'run', 'prf_dag', 'get_data', 'scheduled__2025-02-01T00:00:00+00:00', '--job-id', '20', '--raw', '--subdir', 'DAGS_FOLDER/prf_dag.py', '--cfg-path', '/tmp/tmp7fvo1oew']
[2025-03-26T18:27:46.768+0000] {warnings.py:112} WARNING - /home/***/.local/lib/python3.12/site-packages/***/task/task_runner/standard_task_runner.py:70: DeprecationWarning: This process (pid=569) is multi-threaded, use of fork() may lead to deadlocks in the child.
  pid = os.fork()

[2025-03-26T18:27:46.772+0000] {standard_task_runner.py:105} INFO - Job 20: Subtask get_data
[2025-03-26T18:27:46.777+0000] {standard_task_runner.py:72} INFO - Started process 570 to run task
[2025-03-26T18:27:47.188+0000] {task_command.py:467} INFO - Running <TaskInstance: prf_dag.get_data scheduled__2025-02-01T00:00:00+00:00 [running]> on host 3a60e3c0d2e4
[2025-03-26T18:27:47.584+0000] {taskinstance.py:3131} INFO - Exporting env vars: AIRFLOW_CTX_DAG_OWNER='***' AIRFLOW_CTX_DAG_ID='prf_dag' AIRFLOW_CTX_TASK_ID='get_data' AIRFLOW_CTX_EXECUTION_DATE='2025-02-01T00:00:00+00:00' AIRFLOW_CTX_TRY_NUMBER='2' AIRFLOW_CTX_DAG_RUN_ID='scheduled__2025-02-01T00:00:00+00:00'
[2025-03-26T18:27:47.598+0000] {taskinstance.py:731} INFO - ::endgroup::
[2025-03-26T18:27:51.171+0000] {prf_dag.py:131} INFO - Renamed 'datatran2025.csv' to 'occorência_datatran2025_3.csv'
[2025-03-26T18:28:01.313+0000] {prf_dag.py:131} INFO - Renamed 'acidentes2025.csv' to 'pessoa_acidentes2025_3.csv'
[2025-03-26T18:28:35.509+0000] {job.py:229} INFO - Heartbeat recovered after 26.53 seconds
[2025-03-26T18:28:39.970+0000] {prf_dag.py:131} INFO - Renamed 'acidentes2025_todas_causas_tipos.csv' to 'acidentes2025_todas_causas_tipos_3.csv'
[2025-03-26T18:28:45.203+0000] {job.py:229} INFO - Heartbeat recovered after 16.64 seconds
[2025-03-26T18:28:56.794+0000] {prf_dag.py:131} INFO - Renamed 'datatran2024.csv' to 'occorência_datatran2024_3.csv'
[2025-03-26T18:29:09.899+0000] {prf_dag.py:131} INFO - Renamed 'acidentes2024.csv' to 'pessoa_acidentes2024_3.csv'
[2025-03-26T18:29:25.030+0000] {prf_dag.py:131} INFO - Renamed 'acidentes2024_todas_causas_tipos.csv' to 'acidentes2024_todas_causas_tipos_3.csv'
[2025-03-26T18:29:35.933+0000] {prf_dag.py:131} INFO - Renamed 'datatran2023.csv' to 'occorência_datatran2023_3.csv'
[2025-03-26T18:29:47.000+0000] {prf_dag.py:131} INFO - Renamed 'acidentes2023.csv' to 'pessoa_acidentes2023_3.csv'
[2025-03-26T18:29:57.599+0000] {prf_dag.py:131} INFO - Renamed 'acidentes2023_todas_causas_tipos.csv' to 'acidentes2023_todas_causas_tipos_3.csv'
[2025-03-26T18:30:06.849+0000] {prf_dag.py:131} INFO - Renamed 'datatran2022.csv' to 'occorência_datatran2022_3.csv'
[2025-03-26T18:31:36.923+0000] {job.py:229} INFO - Heartbeat recovered after 92.50 seconds
[2025-03-26T18:31:47.202+0000] {job.py:229} INFO - Heartbeat recovered after 15.10 seconds
[2025-03-26T18:31:48.207+0000] {prf_dag.py:131} INFO - Renamed 'acidentes2022.csv' to 'pessoa_acidentes2022_3.csv'
[2025-03-26T18:32:38.151+0000] {job.py:229} INFO - Heartbeat recovered after 34.30 seconds
[2025-03-26T18:32:49.414+0000] {prf_dag.py:131} INFO - Renamed 'acidentes2022_todas_causas_tipos.csv' to 'acidentes2022_todas_causas_tipos_3.csv'
[2025-03-26T18:33:06.776+0000] {prf_dag.py:131} INFO - Renamed 'datatran2021.csv' to 'occorência_datatran2021_3.csv'
[2025-03-26T18:33:07.486+0000] {job.py:229} INFO - Heartbeat recovered after 11.21 seconds
[2025-03-26T18:33:17.008+0000] {job.py:229} INFO - Heartbeat recovered after 10.93 seconds
[2025-03-26T18:33:27.199+0000] {job.py:229} INFO - Heartbeat recovered after 11.15 seconds
[2025-03-26T18:33:37.655+0000] {prf_dag.py:131} INFO - Renamed 'acidentes2021.csv' to 'pessoa_acidentes2021_3.csv'
[2025-03-26T18:33:37.978+0000] {job.py:229} INFO - Heartbeat recovered after 11.09 seconds
[2025-03-26T18:34:01.625+0000] {prf_dag.py:131} INFO - Renamed 'acidentes2021_todas_causas_tipos.csv' to 'acidentes2021_todas_causas_tipos_3.csv'
[2025-03-26T18:34:12.326+0000] {job.py:229} INFO - Heartbeat recovered after 11.29 seconds
[2025-03-26T18:34:18.736+0000] {prf_dag.py:131} INFO - Renamed 'datatran2020.csv' to 'occorência_datatran2020_3.csv'
[2025-03-26T18:34:26.647+0000] {job.py:229} INFO - Heartbeat recovered after 16.26 seconds
[2025-03-26T18:34:51.474+0000] {job.py:229} INFO - Heartbeat recovered after 25.05 seconds
[2025-03-26T18:34:59.638+0000] {prf_dag.py:131} INFO - Renamed 'acidentes2020.csv' to 'pessoa_acidentes2020_3.csv'
[2025-03-26T18:35:34.362+0000] {taskinstance.py:3310} ERROR - Task failed with exception
Traceback (most recent call last):
  File "/home/airflow/.local/lib/python3.12/site-packages/urllib3/connectionpool.py", line 789, in urlopen
    response = self._make_request(
               ^^^^^^^^^^^^^^^^^^^
  File "/home/airflow/.local/lib/python3.12/site-packages/urllib3/connectionpool.py", line 536, in _make_request
    response = conn.getresponse()
               ^^^^^^^^^^^^^^^^^^
  File "/home/airflow/.local/lib/python3.12/site-packages/urllib3/connection.py", line 464, in getresponse
    httplib_response = super().getresponse()
                       ^^^^^^^^^^^^^^^^^^^^^
  File "/usr/local/lib/python3.12/http/client.py", line 1428, in getresponse
    response.begin()
  File "/usr/local/lib/python3.12/http/client.py", line 331, in begin
    version, status, reason = self._read_status()
                              ^^^^^^^^^^^^^^^^^^^
  File "/usr/local/lib/python3.12/http/client.py", line 300, in _read_status
    raise RemoteDisconnected("Remote end closed connection without"
http.client.RemoteDisconnected: Remote end closed connection without response

During handling of the above exception, another exception occurred:

Traceback (most recent call last):
  File "/home/airflow/.local/lib/python3.12/site-packages/requests/adapters.py", line 667, in send
    resp = conn.urlopen(
           ^^^^^^^^^^^^^
  File "/home/airflow/.local/lib/python3.12/site-packages/urllib3/connectionpool.py", line 843, in urlopen
    retries = retries.increment(
              ^^^^^^^^^^^^^^^^^^
  File "/home/airflow/.local/lib/python3.12/site-packages/urllib3/util/retry.py", line 474, in increment
    raise reraise(type(error), error, _stacktrace)
          ^^^^^^^^^^^^^^^^^^^^^^^^^^^^^^^^^^^^^^^^
  File "/home/airflow/.local/lib/python3.12/site-packages/urllib3/util/util.py", line 38, in reraise
    raise value.with_traceback(tb)
  File "/home/airflow/.local/lib/python3.12/site-packages/urllib3/connectionpool.py", line 789, in urlopen
    response = self._make_request(
               ^^^^^^^^^^^^^^^^^^^
  File "/home/airflow/.local/lib/python3.12/site-packages/urllib3/connectionpool.py", line 536, in _make_request
    response = conn.getresponse()
               ^^^^^^^^^^^^^^^^^^
  File "/home/airflow/.local/lib/python3.12/site-packages/urllib3/connection.py", line 464, in getresponse
    httplib_response = super().getresponse()
                       ^^^^^^^^^^^^^^^^^^^^^
  File "/usr/local/lib/python3.12/http/client.py", line 1428, in getresponse
    response.begin()
  File "/usr/local/lib/python3.12/http/client.py", line 331, in begin
    version, status, reason = self._read_status()
                              ^^^^^^^^^^^^^^^^^^^
  File "/usr/local/lib/python3.12/http/client.py", line 300, in _read_status
    raise RemoteDisconnected("Remote end closed connection without"
urllib3.exceptions.ProtocolError: ('Connection aborted.', RemoteDisconnected('Remote end closed connection without response'))

During handling of the above exception, another exception occurred:

Traceback (most recent call last):
  File "/home/airflow/.local/lib/python3.12/site-packages/airflow/models/taskinstance.py", line 767, in _execute_task
    result = _execute_callable(context=context, **execute_callable_kwargs)
             ^^^^^^^^^^^^^^^^^^^^^^^^^^^^^^^^^^^^^^^^^^^^^^^^^^^^^^^^^^^^^
  File "/home/airflow/.local/lib/python3.12/site-packages/airflow/models/taskinstance.py", line 733, in _execute_callable
    return ExecutionCallableRunner(
           ^^^^^^^^^^^^^^^^^^^^^^^^
  File "/home/airflow/.local/lib/python3.12/site-packages/airflow/utils/operator_helpers.py", line 252, in run
    return self.func(*args, **kwargs)
           ^^^^^^^^^^^^^^^^^^^^^^^^^^
  File "/home/airflow/.local/lib/python3.12/site-packages/airflow/models/baseoperator.py", line 406, in wrapper
    return func(self, *args, **kwargs)
           ^^^^^^^^^^^^^^^^^^^^^^^^^^^
  File "/home/airflow/.local/lib/python3.12/site-packages/airflow/decorators/base.py", line 266, in execute
    return_value = super().execute(context)
                   ^^^^^^^^^^^^^^^^^^^^^^^^
  File "/home/airflow/.local/lib/python3.12/site-packages/airflow/models/baseoperator.py", line 406, in wrapper
    return func(self, *args, **kwargs)
           ^^^^^^^^^^^^^^^^^^^^^^^^^^^
  File "/home/airflow/.local/lib/python3.12/site-packages/airflow/operators/python.py", line 238, in execute
    return_value = self.execute_callable()
                   ^^^^^^^^^^^^^^^^^^^^^^^
  File "/home/airflow/.local/lib/python3.12/site-packages/airflow/operators/python.py", line 256, in execute_callable
    return runner.run(*self.op_args, **self.op_kwargs)
           ^^^^^^^^^^^^^^^^^^^^^^^^^^^^^^^^^^^^^^^^^^^
  File "/home/airflow/.local/lib/python3.12/site-packages/airflow/utils/operator_helpers.py", line 252, in run
    return self.func(*args, **kwargs)
           ^^^^^^^^^^^^^^^^^^^^^^^^^^
  File "/opt/airflow/dags/prf_dag.py", line 93, in get_data
    response = requests.get(final_url)
               ^^^^^^^^^^^^^^^^^^^^^^^
  File "/home/airflow/.local/lib/python3.12/site-packages/requests/api.py", line 73, in get
    return request("get", url, params=params, **kwargs)
           ^^^^^^^^^^^^^^^^^^^^^^^^^^^^^^^^^^^^^^^^^^^^
  File "/home/airflow/.local/lib/python3.12/site-packages/requests/api.py", line 59, in request
    return session.request(method=method, url=url, **kwargs)
           ^^^^^^^^^^^^^^^^^^^^^^^^^^^^^^^^^^^^^^^^^^^^^^^^^
  File "/home/airflow/.local/lib/python3.12/site-packages/requests/sessions.py", line 589, in request
    resp = self.send(prep, **send_kwargs)
           ^^^^^^^^^^^^^^^^^^^^^^^^^^^^^^
  File "/home/airflow/.local/lib/python3.12/site-packages/requests/sessions.py", line 703, in send
    r = adapter.send(request, **kwargs)
        ^^^^^^^^^^^^^^^^^^^^^^^^^^^^^^^
  File "/home/airflow/.local/lib/python3.12/site-packages/requests/adapters.py", line 682, in send
    raise ConnectionError(err, request=request)
requests.exceptions.ConnectionError: ('Connection aborted.', RemoteDisconnected('Remote end closed connection without response'))
[2025-03-26T18:35:56.456+0000] {taskinstance.py:1225} INFO - Marking task as UP_FOR_RETRY. dag_id=prf_dag, task_id=get_data, run_id=scheduled__2025-02-01T00:00:00+00:00, execution_date=20250201T000000, start_date=20250326T182746, end_date=20250326T183555
[2025-03-26T18:35:56.435+0000] {job.py:229} INFO - Heartbeat recovered after 66.23 seconds
[2025-03-26T18:36:30.479+0000] {taskinstance.py:340} INFO - ::group::Post task execution logs
[2025-03-26T18:36:33.431+0000] {standard_task_runner.py:124} ERROR - Failed to execute job 20 for task get_data (('Connection aborted.', RemoteDisconnected('Remote end closed connection without response')); 570)
Traceback (most recent call last):
  File "/home/airflow/.local/lib/python3.12/site-packages/urllib3/connectionpool.py", line 789, in urlopen
    response = self._make_request(
               ^^^^^^^^^^^^^^^^^^^
  File "/home/airflow/.local/lib/python3.12/site-packages/urllib3/connectionpool.py", line 536, in _make_request
    response = conn.getresponse()
               ^^^^^^^^^^^^^^^^^^
  File "/home/airflow/.local/lib/python3.12/site-packages/urllib3/connection.py", line 464, in getresponse
    httplib_response = super().getresponse()
                       ^^^^^^^^^^^^^^^^^^^^^
  File "/usr/local/lib/python3.12/http/client.py", line 1428, in getresponse
    response.begin()
  File "/usr/local/lib/python3.12/http/client.py", line 331, in begin
    version, status, reason = self._read_status()
                              ^^^^^^^^^^^^^^^^^^^
  File "/usr/local/lib/python3.12/http/client.py", line 300, in _read_status
    raise RemoteDisconnected("Remote end closed connection without"
http.client.RemoteDisconnected: Remote end closed connection without response

During handling of the above exception, another exception occurred:

Traceback (most recent call last):
  File "/home/airflow/.local/lib/python3.12/site-packages/requests/adapters.py", line 667, in send
    resp = conn.urlopen(
           ^^^^^^^^^^^^^
  File "/home/airflow/.local/lib/python3.12/site-packages/urllib3/connectionpool.py", line 843, in urlopen
    retries = retries.increment(
              ^^^^^^^^^^^^^^^^^^
  File "/home/airflow/.local/lib/python3.12/site-packages/urllib3/util/retry.py", line 474, in increment
    raise reraise(type(error), error, _stacktrace)
          ^^^^^^^^^^^^^^^^^^^^^^^^^^^^^^^^^^^^^^^^
  File "/home/airflow/.local/lib/python3.12/site-packages/urllib3/util/util.py", line 38, in reraise
    raise value.with_traceback(tb)
  File "/home/airflow/.local/lib/python3.12/site-packages/urllib3/connectionpool.py", line 789, in urlopen
    response = self._make_request(
               ^^^^^^^^^^^^^^^^^^^
  File "/home/airflow/.local/lib/python3.12/site-packages/urllib3/connectionpool.py", line 536, in _make_request
    response = conn.getresponse()
               ^^^^^^^^^^^^^^^^^^
  File "/home/airflow/.local/lib/python3.12/site-packages/urllib3/connection.py", line 464, in getresponse
    httplib_response = super().getresponse()
                       ^^^^^^^^^^^^^^^^^^^^^
  File "/usr/local/lib/python3.12/http/client.py", line 1428, in getresponse
    response.begin()
  File "/usr/local/lib/python3.12/http/client.py", line 331, in begin
    version, status, reason = self._read_status()
                              ^^^^^^^^^^^^^^^^^^^
  File "/usr/local/lib/python3.12/http/client.py", line 300, in _read_status
    raise RemoteDisconnected("Remote end closed connection without"
urllib3.exceptions.ProtocolError: ('Connection aborted.', RemoteDisconnected('Remote end closed connection without response'))

During handling of the above exception, another exception occurred:

Traceback (most recent call last):
  File "/home/airflow/.local/lib/python3.12/site-packages/airflow/task/task_runner/standard_task_runner.py", line 117, in _start_by_fork
    ret = args.func(args, dag=self.dag)
          ^^^^^^^^^^^^^^^^^^^^^^^^^^^^^
  File "/home/airflow/.local/lib/python3.12/site-packages/airflow/cli/cli_config.py", line 49, in command
    return func(*args, **kwargs)
           ^^^^^^^^^^^^^^^^^^^^^
  File "/home/airflow/.local/lib/python3.12/site-packages/airflow/utils/cli.py", line 115, in wrapper
    return f(*args, **kwargs)
           ^^^^^^^^^^^^^^^^^^
  File "/home/airflow/.local/lib/python3.12/site-packages/airflow/cli/commands/task_command.py", line 483, in task_run
    task_return_code = _run_task_by_selected_method(args, _dag, ti)
                       ^^^^^^^^^^^^^^^^^^^^^^^^^^^^^^^^^^^^^^^^^^^^
  File "/home/airflow/.local/lib/python3.12/site-packages/airflow/cli/commands/task_command.py", line 256, in _run_task_by_selected_method
    return _run_raw_task(args, ti)
           ^^^^^^^^^^^^^^^^^^^^^^^
  File "/home/airflow/.local/lib/python3.12/site-packages/airflow/cli/commands/task_command.py", line 341, in _run_raw_task
    return ti._run_raw_task(
           ^^^^^^^^^^^^^^^^^
  File "/home/airflow/.local/lib/python3.12/site-packages/airflow/utils/session.py", line 97, in wrapper
    return func(*args, session=session, **kwargs)
           ^^^^^^^^^^^^^^^^^^^^^^^^^^^^^^^^^^^^^^
  File "/home/airflow/.local/lib/python3.12/site-packages/airflow/models/taskinstance.py", line 3004, in _run_raw_task
    return _run_raw_task(
           ^^^^^^^^^^^^^^
  File "/home/airflow/.local/lib/python3.12/site-packages/airflow/models/taskinstance.py", line 273, in _run_raw_task
    TaskInstance._execute_task_with_callbacks(
  File "/home/airflow/.local/lib/python3.12/site-packages/airflow/models/taskinstance.py", line 3158, in _execute_task_with_callbacks
    result = self._execute_task(context, task_orig)
             ^^^^^^^^^^^^^^^^^^^^^^^^^^^^^^^^^^^^^^
  File "/home/airflow/.local/lib/python3.12/site-packages/airflow/models/taskinstance.py", line 3182, in _execute_task
    return _execute_task(self, context, task_orig)
           ^^^^^^^^^^^^^^^^^^^^^^^^^^^^^^^^^^^^^^^
  File "/home/airflow/.local/lib/python3.12/site-packages/airflow/models/taskinstance.py", line 767, in _execute_task
    result = _execute_callable(context=context, **execute_callable_kwargs)
             ^^^^^^^^^^^^^^^^^^^^^^^^^^^^^^^^^^^^^^^^^^^^^^^^^^^^^^^^^^^^^
  File "/home/airflow/.local/lib/python3.12/site-packages/airflow/models/taskinstance.py", line 733, in _execute_callable
    return ExecutionCallableRunner(
           ^^^^^^^^^^^^^^^^^^^^^^^^
  File "/home/airflow/.local/lib/python3.12/site-packages/airflow/utils/operator_helpers.py", line 252, in run
    return self.func(*args, **kwargs)
           ^^^^^^^^^^^^^^^^^^^^^^^^^^
  File "/home/airflow/.local/lib/python3.12/site-packages/airflow/models/baseoperator.py", line 406, in wrapper
    return func(self, *args, **kwargs)
           ^^^^^^^^^^^^^^^^^^^^^^^^^^^
  File "/home/airflow/.local/lib/python3.12/site-packages/airflow/decorators/base.py", line 266, in execute
    return_value = super().execute(context)
                   ^^^^^^^^^^^^^^^^^^^^^^^^
  File "/home/airflow/.local/lib/python3.12/site-packages/airflow/models/baseoperator.py", line 406, in wrapper
    return func(self, *args, **kwargs)
           ^^^^^^^^^^^^^^^^^^^^^^^^^^^
  File "/home/airflow/.local/lib/python3.12/site-packages/airflow/operators/python.py", line 238, in execute
    return_value = self.execute_callable()
                   ^^^^^^^^^^^^^^^^^^^^^^^
  File "/home/airflow/.local/lib/python3.12/site-packages/airflow/operators/python.py", line 256, in execute_callable
    return runner.run(*self.op_args, **self.op_kwargs)
           ^^^^^^^^^^^^^^^^^^^^^^^^^^^^^^^^^^^^^^^^^^^
  File "/home/airflow/.local/lib/python3.12/site-packages/airflow/utils/operator_helpers.py", line 252, in run
    return self.func(*args, **kwargs)
           ^^^^^^^^^^^^^^^^^^^^^^^^^^
  File "/opt/airflow/dags/prf_dag.py", line 93, in get_data
    response = requests.get(final_url)
               ^^^^^^^^^^^^^^^^^^^^^^^
  File "/home/airflow/.local/lib/python3.12/site-packages/requests/api.py", line 73, in get
    return request("get", url, params=params, **kwargs)
           ^^^^^^^^^^^^^^^^^^^^^^^^^^^^^^^^^^^^^^^^^^^^
  File "/home/airflow/.local/lib/python3.12/site-packages/requests/api.py", line 59, in request
    return session.request(method=method, url=url, **kwargs)
           ^^^^^^^^^^^^^^^^^^^^^^^^^^^^^^^^^^^^^^^^^^^^^^^^^
  File "/home/airflow/.local/lib/python3.12/site-packages/requests/sessions.py", line 589, in request
    resp = self.send(prep, **send_kwargs)
           ^^^^^^^^^^^^^^^^^^^^^^^^^^^^^^
  File "/home/airflow/.local/lib/python3.12/site-packages/requests/sessions.py", line 703, in send
    r = adapter.send(request, **kwargs)
        ^^^^^^^^^^^^^^^^^^^^^^^^^^^^^^^
  File "/home/airflow/.local/lib/python3.12/site-packages/requests/adapters.py", line 682, in send
    raise ConnectionError(err, request=request)
requests.exceptions.ConnectionError: ('Connection aborted.', RemoteDisconnected('Remote end closed connection without response'))
[2025-03-26T18:36:46.126+0000] {job.py:229} INFO - Heartbeat recovered after 51.23 seconds
[2025-03-26T18:36:49.369+0000] {local_task_job_runner.py:266} INFO - Task exited with return code 1
[2025-03-26T18:36:50.004+0000] {standard_task_runner.py:217} INFO - Process not found (most likely exited), stop collecting metrics
[2025-03-26T18:37:24.447+0000] {taskinstance.py:3900} INFO - 0 downstream tasks scheduled from follow-on schedule check
