[2025-03-25T22:36:39.019+0000] {local_task_job_runner.py:123} INFO - ::group::Pre task execution logs
[2025-03-25T22:36:39.136+0000] {taskinstance.py:2612} INFO - Dependencies all met for dep_context=non-requeueable deps ti=<TaskInstance: get_inaturalist_data_roadkill.save_data scheduled__2025-03-25T22:00:00+00:00 [queued]>
[2025-03-25T22:36:39.183+0000] {taskinstance.py:2612} INFO - Dependencies all met for dep_context=requeueable deps ti=<TaskInstance: get_inaturalist_data_roadkill.save_data scheduled__2025-03-25T22:00:00+00:00 [queued]>
[2025-03-25T22:36:39.189+0000] {taskinstance.py:2865} INFO - Starting attempt 1 of 4
[2025-03-25T22:36:39.239+0000] {taskinstance.py:2888} INFO - Executing <Task(_PythonDecoratedOperator): save_data> on 2025-03-25 22:00:00+00:00
[2025-03-25T22:36:39.258+0000] {warnings.py:112} WARNING - /home/***/.local/lib/python3.12/site-packages/***/task/task_runner/standard_task_runner.py:70: DeprecationWarning: This process (pid=1859) is multi-threaded, use of fork() may lead to deadlocks in the child.
  pid = os.fork()

[2025-03-25T22:36:39.269+0000] {standard_task_runner.py:72} INFO - Started process 1861 to run task
[2025-03-25T22:36:39.261+0000] {standard_task_runner.py:104} INFO - Running: ['***', 'tasks', 'run', 'get_inaturalist_data_roadkill', 'save_data', 'scheduled__2025-03-25T22:00:00+00:00', '--job-id', '125', '--raw', '--subdir', 'DAGS_FOLDER/inaturalist_dag.py', '--cfg-path', '/tmp/tmpaue3kymt']
[2025-03-25T22:36:39.284+0000] {standard_task_runner.py:105} INFO - Job 125: Subtask save_data
[2025-03-25T22:36:39.550+0000] {task_command.py:467} INFO - Running <TaskInstance: get_inaturalist_data_roadkill.save_data scheduled__2025-03-25T22:00:00+00:00 [running]> on host 5ed333479984
[2025-03-25T22:36:40.785+0000] {taskinstance.py:3131} INFO - Exporting env vars: AIRFLOW_CTX_DAG_OWNER='***' AIRFLOW_CTX_DAG_ID='get_inaturalist_data_roadkill' AIRFLOW_CTX_TASK_ID='save_data' AIRFLOW_CTX_EXECUTION_DATE='2025-03-25T22:00:00+00:00' AIRFLOW_CTX_TRY_NUMBER='1' AIRFLOW_CTX_DAG_RUN_ID='scheduled__2025-03-25T22:00:00+00:00'
[2025-03-25T22:36:40.800+0000] {taskinstance.py:731} INFO - ::endgroup::
[2025-03-25T22:36:47.355+0000] {connectionpool.py:870} WARNING - Retrying (Retry(total=4, connect=None, read=None, redirect=None, status=None)) after connection broken by 'NewConnectionError('<urllib3.connection.HTTPConnection object at 0xffff8be8daf0>: Failed to establish a new connection: [Errno 111] Connection refused')': /environbit?location=
[2025-03-25T22:36:53.855+0000] {connectionpool.py:870} WARNING - Retrying (Retry(total=3, connect=None, read=None, redirect=None, status=None)) after connection broken by 'NewConnectionError('<urllib3.connection.HTTPConnection object at 0xffff8be8ddc0>: Failed to establish a new connection: [Errno 111] Connection refused')': /environbit?location=
[2025-03-25T22:37:00.720+0000] {connectionpool.py:870} WARNING - Retrying (Retry(total=2, connect=None, read=None, redirect=None, status=None)) after connection broken by 'NewConnectionError('<urllib3.connection.HTTPConnection object at 0xffff8be8df70>: Failed to establish a new connection: [Errno 111] Connection refused')': /environbit?location=
[2025-03-25T22:37:09.047+0000] {connectionpool.py:870} WARNING - Retrying (Retry(total=1, connect=None, read=None, redirect=None, status=None)) after connection broken by 'NewConnectionError('<urllib3.connection.HTTPConnection object at 0xffff8be8e510>: Failed to establish a new connection: [Errno 111] Connection refused')': /environbit?location=
